[2024-03-27T19:09:22.989+0000] {processor.py:154} INFO - Started process (PID=33) to work on /opt/airflow/dags/consumer.py
[2024-03-27T19:09:22.991+0000] {processor.py:756} INFO - Processing file /opt/airflow/dags/consumer.py for tasks to queue
[2024-03-27T19:09:22.992+0000] {logging_mixin.py:120} INFO - [2024-03-27T19:09:22.991+0000] {dagbag.py:537} INFO - Filling up the DagBag from /opt/airflow/dags/consumer.py
[2024-03-27T19:09:23.027+0000] {logging_mixin.py:120} INFO - [2024-03-27T19:09:23.026+0000] {dagbag.py:342} ERROR - Failed to import: /opt/airflow/dags/consumer.py
Traceback (most recent call last):
  File "/home/airflow/.local/lib/python3.7/site-packages/airflow/models/dagbag.py", line 338, in parse
    loader.exec_module(new_module)
  File "<frozen importlib._bootstrap_external>", line 728, in exec_module
  File "<frozen importlib._bootstrap>", line 219, in _call_with_frames_removed
  File "/opt/airflow/dags/consumer.py", line 13, in <module>
    catchup=False
TypeError: __init__() got an unexpected keyword argument 'task_id'
[2024-03-27T19:09:23.028+0000] {processor.py:768} WARNING - No viable dags retrieved from /opt/airflow/dags/consumer.py
[2024-03-27T19:09:23.053+0000] {processor.py:176} INFO - Processing /opt/airflow/dags/consumer.py took 0.067 seconds
[2024-03-27T19:09:53.068+0000] {processor.py:154} INFO - Started process (PID=83) to work on /opt/airflow/dags/consumer.py
[2024-03-27T19:09:53.071+0000] {processor.py:756} INFO - Processing file /opt/airflow/dags/consumer.py for tasks to queue
[2024-03-27T19:09:53.074+0000] {logging_mixin.py:120} INFO - [2024-03-27T19:09:53.074+0000] {dagbag.py:537} INFO - Filling up the DagBag from /opt/airflow/dags/consumer.py
[2024-03-27T19:09:53.096+0000] {logging_mixin.py:120} INFO - [2024-03-27T19:09:53.091+0000] {dagbag.py:342} ERROR - Failed to import: /opt/airflow/dags/consumer.py
Traceback (most recent call last):
  File "/home/airflow/.local/lib/python3.7/site-packages/airflow/models/dagbag.py", line 338, in parse
    loader.exec_module(new_module)
  File "<frozen importlib._bootstrap_external>", line 728, in exec_module
  File "<frozen importlib._bootstrap>", line 219, in _call_with_frames_removed
  File "/opt/airflow/dags/consumer.py", line 13, in <module>
    catchup=False
TypeError: __init__() got an unexpected keyword argument 'task_id'
[2024-03-27T19:09:53.097+0000] {processor.py:768} WARNING - No viable dags retrieved from /opt/airflow/dags/consumer.py
[2024-03-27T19:09:53.121+0000] {processor.py:176} INFO - Processing /opt/airflow/dags/consumer.py took 0.055 seconds
[2024-03-27T19:10:23.344+0000] {processor.py:154} INFO - Started process (PID=150) to work on /opt/airflow/dags/consumer.py
[2024-03-27T19:10:23.346+0000] {processor.py:756} INFO - Processing file /opt/airflow/dags/consumer.py for tasks to queue
[2024-03-27T19:10:23.350+0000] {logging_mixin.py:120} INFO - [2024-03-27T19:10:23.349+0000] {dagbag.py:537} INFO - Filling up the DagBag from /opt/airflow/dags/consumer.py
[2024-03-27T19:10:23.378+0000] {logging_mixin.py:120} INFO - [2024-03-27T19:10:23.374+0000] {dagbag.py:342} ERROR - Failed to import: /opt/airflow/dags/consumer.py
Traceback (most recent call last):
  File "/home/airflow/.local/lib/python3.7/site-packages/airflow/models/dagbag.py", line 338, in parse
    loader.exec_module(new_module)
  File "<frozen importlib._bootstrap_external>", line 728, in exec_module
  File "<frozen importlib._bootstrap>", line 219, in _call_with_frames_removed
  File "/opt/airflow/dags/consumer.py", line 13, in <module>
    catchup=False
TypeError: __init__() got an unexpected keyword argument 'task_id'
[2024-03-27T19:10:23.380+0000] {processor.py:768} WARNING - No viable dags retrieved from /opt/airflow/dags/consumer.py
[2024-03-27T19:10:23.401+0000] {processor.py:176} INFO - Processing /opt/airflow/dags/consumer.py took 0.070 seconds
[2024-03-27T19:10:38.489+0000] {processor.py:154} INFO - Started process (PID=33) to work on /opt/airflow/dags/consumer.py
[2024-03-27T19:10:38.491+0000] {processor.py:756} INFO - Processing file /opt/airflow/dags/consumer.py for tasks to queue
[2024-03-27T19:10:38.494+0000] {logging_mixin.py:120} INFO - [2024-03-27T19:10:38.493+0000] {dagbag.py:537} INFO - Filling up the DagBag from /opt/airflow/dags/consumer.py
[2024-03-27T19:10:38.539+0000] {logging_mixin.py:120} INFO - [2024-03-27T19:10:38.537+0000] {dagbag.py:342} ERROR - Failed to import: /opt/airflow/dags/consumer.py
Traceback (most recent call last):
  File "/home/airflow/.local/lib/python3.7/site-packages/airflow/models/dagbag.py", line 338, in parse
    loader.exec_module(new_module)
  File "<frozen importlib._bootstrap_external>", line 728, in exec_module
  File "<frozen importlib._bootstrap>", line 219, in _call_with_frames_removed
  File "/opt/airflow/dags/consumer.py", line 13, in <module>
    catchup=False
TypeError: __init__() got an unexpected keyword argument 'task_id'
[2024-03-27T19:10:38.539+0000] {processor.py:768} WARNING - No viable dags retrieved from /opt/airflow/dags/consumer.py
[2024-03-27T19:10:38.583+0000] {processor.py:176} INFO - Processing /opt/airflow/dags/consumer.py took 0.098 seconds
[2024-03-27T19:11:11.901+0000] {processor.py:154} INFO - Started process (PID=83) to work on /opt/airflow/dags/consumer.py
[2024-03-27T19:11:11.905+0000] {processor.py:756} INFO - Processing file /opt/airflow/dags/consumer.py for tasks to queue
[2024-03-27T19:11:11.908+0000] {logging_mixin.py:120} INFO - [2024-03-27T19:11:11.908+0000] {dagbag.py:537} INFO - Filling up the DagBag from /opt/airflow/dags/consumer.py
[2024-03-27T19:11:11.958+0000] {logging_mixin.py:120} INFO - [2024-03-27T19:11:11.952+0000] {dagbag.py:342} ERROR - Failed to import: /opt/airflow/dags/consumer.py
Traceback (most recent call last):
  File "/home/airflow/.local/lib/python3.7/site-packages/airflow/models/dagbag.py", line 338, in parse
    loader.exec_module(new_module)
  File "<frozen importlib._bootstrap_external>", line 728, in exec_module
  File "<frozen importlib._bootstrap>", line 219, in _call_with_frames_removed
  File "/opt/airflow/dags/consumer.py", line 13, in <module>
    catchup=False
TypeError: __init__() got an unexpected keyword argument 'task_id'
[2024-03-27T19:11:11.962+0000] {processor.py:768} WARNING - No viable dags retrieved from /opt/airflow/dags/consumer.py
[2024-03-27T19:11:11.995+0000] {processor.py:176} INFO - Processing /opt/airflow/dags/consumer.py took 0.098 seconds
[2024-03-27T19:11:43.420+0000] {processor.py:154} INFO - Started process (PID=140) to work on /opt/airflow/dags/consumer.py
[2024-03-27T19:11:43.424+0000] {processor.py:756} INFO - Processing file /opt/airflow/dags/consumer.py for tasks to queue
[2024-03-27T19:11:43.426+0000] {logging_mixin.py:120} INFO - [2024-03-27T19:11:43.426+0000] {dagbag.py:537} INFO - Filling up the DagBag from /opt/airflow/dags/consumer.py
[2024-03-27T19:11:43.483+0000] {logging_mixin.py:120} INFO - [2024-03-27T19:11:43.474+0000] {dagbag.py:342} ERROR - Failed to import: /opt/airflow/dags/consumer.py
Traceback (most recent call last):
  File "/home/airflow/.local/lib/python3.7/site-packages/airflow/models/dagbag.py", line 338, in parse
    loader.exec_module(new_module)
  File "<frozen importlib._bootstrap_external>", line 728, in exec_module
  File "<frozen importlib._bootstrap>", line 219, in _call_with_frames_removed
  File "/opt/airflow/dags/consumer.py", line 13, in <module>
    catchup=False
TypeError: __init__() got an unexpected keyword argument 'task_id'
[2024-03-27T19:11:43.484+0000] {processor.py:768} WARNING - No viable dags retrieved from /opt/airflow/dags/consumer.py
[2024-03-27T19:11:43.532+0000] {processor.py:176} INFO - Processing /opt/airflow/dags/consumer.py took 0.123 seconds
[2024-03-27T19:12:18.995+0000] {processor.py:154} INFO - Started process (PID=44) to work on /opt/airflow/dags/consumer.py
[2024-03-27T19:12:18.999+0000] {processor.py:756} INFO - Processing file /opt/airflow/dags/consumer.py for tasks to queue
[2024-03-27T19:12:19.001+0000] {logging_mixin.py:120} INFO - [2024-03-27T19:12:19.000+0000] {dagbag.py:537} INFO - Filling up the DagBag from /opt/airflow/dags/consumer.py
[2024-03-27T19:12:19.038+0000] {logging_mixin.py:120} INFO - [2024-03-27T19:12:19.035+0000] {dagbag.py:342} ERROR - Failed to import: /opt/airflow/dags/consumer.py
Traceback (most recent call last):
  File "/home/airflow/.local/lib/python3.7/site-packages/airflow/models/dagbag.py", line 338, in parse
    loader.exec_module(new_module)
  File "<frozen importlib._bootstrap_external>", line 728, in exec_module
  File "<frozen importlib._bootstrap>", line 219, in _call_with_frames_removed
  File "/opt/airflow/dags/consumer.py", line 13, in <module>
    catchup=False
TypeError: __init__() got an unexpected keyword argument 'task_id'
[2024-03-27T19:12:19.039+0000] {processor.py:768} WARNING - No viable dags retrieved from /opt/airflow/dags/consumer.py
[2024-03-27T19:12:19.099+0000] {processor.py:176} INFO - Processing /opt/airflow/dags/consumer.py took 0.114 seconds
[2024-03-27T19:12:49.533+0000] {processor.py:154} INFO - Started process (PID=94) to work on /opt/airflow/dags/consumer.py
[2024-03-27T19:12:49.538+0000] {processor.py:756} INFO - Processing file /opt/airflow/dags/consumer.py for tasks to queue
[2024-03-27T19:12:49.539+0000] {logging_mixin.py:120} INFO - [2024-03-27T19:12:49.538+0000] {dagbag.py:537} INFO - Filling up the DagBag from /opt/airflow/dags/consumer.py
[2024-03-27T19:12:49.601+0000] {logging_mixin.py:120} INFO - [2024-03-27T19:12:49.594+0000] {dagbag.py:342} ERROR - Failed to import: /opt/airflow/dags/consumer.py
Traceback (most recent call last):
  File "/home/airflow/.local/lib/python3.7/site-packages/airflow/models/dagbag.py", line 338, in parse
    loader.exec_module(new_module)
  File "<frozen importlib._bootstrap_external>", line 728, in exec_module
  File "<frozen importlib._bootstrap>", line 219, in _call_with_frames_removed
  File "/opt/airflow/dags/consumer.py", line 13, in <module>
    catchup=False
TypeError: __init__() got an unexpected keyword argument 'task_id'
[2024-03-27T19:12:49.605+0000] {processor.py:768} WARNING - No viable dags retrieved from /opt/airflow/dags/consumer.py
[2024-03-27T19:12:49.699+0000] {processor.py:176} INFO - Processing /opt/airflow/dags/consumer.py took 0.171 seconds
[2024-03-27T19:13:24.750+0000] {processor.py:154} INFO - Started process (PID=154) to work on /opt/airflow/dags/consumer.py
[2024-03-27T19:13:24.755+0000] {processor.py:756} INFO - Processing file /opt/airflow/dags/consumer.py for tasks to queue
[2024-03-27T19:13:24.761+0000] {logging_mixin.py:120} INFO - [2024-03-27T19:13:24.761+0000] {dagbag.py:537} INFO - Filling up the DagBag from /opt/airflow/dags/consumer.py
[2024-03-27T19:13:24.988+0000] {logging_mixin.py:120} INFO - [2024-03-27T19:13:24.966+0000] {dagbag.py:342} ERROR - Failed to import: /opt/airflow/dags/consumer.py
Traceback (most recent call last):
  File "/home/airflow/.local/lib/python3.7/site-packages/airflow/models/dagbag.py", line 338, in parse
    loader.exec_module(new_module)
  File "<frozen importlib._bootstrap_external>", line 728, in exec_module
  File "<frozen importlib._bootstrap>", line 219, in _call_with_frames_removed
  File "/opt/airflow/dags/consumer.py", line 13, in <module>
    catchup=False
TypeError: __init__() got an unexpected keyword argument 'task_id'
[2024-03-27T19:13:24.992+0000] {processor.py:768} WARNING - No viable dags retrieved from /opt/airflow/dags/consumer.py
[2024-03-27T19:13:25.117+0000] {processor.py:176} INFO - Processing /opt/airflow/dags/consumer.py took 0.422 seconds
[2024-03-27T19:13:55.618+0000] {processor.py:154} INFO - Started process (PID=43) to work on /opt/airflow/dags/consumer.py
[2024-03-27T19:13:55.621+0000] {processor.py:756} INFO - Processing file /opt/airflow/dags/consumer.py for tasks to queue
[2024-03-27T19:13:55.622+0000] {logging_mixin.py:120} INFO - [2024-03-27T19:13:55.622+0000] {dagbag.py:537} INFO - Filling up the DagBag from /opt/airflow/dags/consumer.py
[2024-03-27T19:13:55.635+0000] {logging_mixin.py:120} INFO - [2024-03-27T19:13:55.634+0000] {dagbag.py:342} ERROR - Failed to import: /opt/airflow/dags/consumer.py
Traceback (most recent call last):
  File "/home/airflow/.local/lib/python3.7/site-packages/airflow/models/dagbag.py", line 338, in parse
    loader.exec_module(new_module)
  File "<frozen importlib._bootstrap_external>", line 728, in exec_module
  File "<frozen importlib._bootstrap>", line 219, in _call_with_frames_removed
  File "/opt/airflow/dags/consumer.py", line 13, in <module>
    catchup=False
TypeError: __init__() got an unexpected keyword argument 'task_id'
[2024-03-27T19:13:55.636+0000] {processor.py:768} WARNING - No viable dags retrieved from /opt/airflow/dags/consumer.py
[2024-03-27T19:13:55.655+0000] {processor.py:176} INFO - Processing /opt/airflow/dags/consumer.py took 0.039 seconds
[2024-03-27T19:14:26.275+0000] {processor.py:154} INFO - Started process (PID=93) to work on /opt/airflow/dags/consumer.py
[2024-03-27T19:14:26.276+0000] {processor.py:756} INFO - Processing file /opt/airflow/dags/consumer.py for tasks to queue
[2024-03-27T19:14:26.277+0000] {logging_mixin.py:120} INFO - [2024-03-27T19:14:26.277+0000] {dagbag.py:537} INFO - Filling up the DagBag from /opt/airflow/dags/consumer.py
[2024-03-27T19:14:26.301+0000] {logging_mixin.py:120} INFO - [2024-03-27T19:14:26.299+0000] {dagbag.py:342} ERROR - Failed to import: /opt/airflow/dags/consumer.py
Traceback (most recent call last):
  File "/home/airflow/.local/lib/python3.7/site-packages/airflow/models/dagbag.py", line 338, in parse
    loader.exec_module(new_module)
  File "<frozen importlib._bootstrap_external>", line 728, in exec_module
  File "<frozen importlib._bootstrap>", line 219, in _call_with_frames_removed
  File "/opt/airflow/dags/consumer.py", line 13, in <module>
    catchup=False
TypeError: __init__() got an unexpected keyword argument 'task_id'
[2024-03-27T19:14:26.302+0000] {processor.py:768} WARNING - No viable dags retrieved from /opt/airflow/dags/consumer.py
[2024-03-27T19:14:26.328+0000] {processor.py:176} INFO - Processing /opt/airflow/dags/consumer.py took 0.058 seconds
[2024-03-27T19:14:57.047+0000] {processor.py:154} INFO - Started process (PID=153) to work on /opt/airflow/dags/consumer.py
[2024-03-27T19:14:57.049+0000] {processor.py:756} INFO - Processing file /opt/airflow/dags/consumer.py for tasks to queue
[2024-03-27T19:14:57.051+0000] {logging_mixin.py:120} INFO - [2024-03-27T19:14:57.051+0000] {dagbag.py:537} INFO - Filling up the DagBag from /opt/airflow/dags/consumer.py
[2024-03-27T19:14:57.090+0000] {logging_mixin.py:120} INFO - [2024-03-27T19:14:57.083+0000] {dagbag.py:342} ERROR - Failed to import: /opt/airflow/dags/consumer.py
Traceback (most recent call last):
  File "/home/airflow/.local/lib/python3.7/site-packages/airflow/models/dagbag.py", line 338, in parse
    loader.exec_module(new_module)
  File "<frozen importlib._bootstrap_external>", line 728, in exec_module
  File "<frozen importlib._bootstrap>", line 219, in _call_with_frames_removed
  File "/opt/airflow/dags/consumer.py", line 13, in <module>
    catchup=False
TypeError: __init__() got an unexpected keyword argument 'task_id'
[2024-03-27T19:14:57.092+0000] {processor.py:768} WARNING - No viable dags retrieved from /opt/airflow/dags/consumer.py
[2024-03-27T19:14:57.137+0000] {processor.py:176} INFO - Processing /opt/airflow/dags/consumer.py took 0.103 seconds
[2024-03-27T19:15:20.144+0000] {processor.py:154} INFO - Started process (PID=43) to work on /opt/airflow/dags/consumer.py
[2024-03-27T19:15:20.146+0000] {processor.py:756} INFO - Processing file /opt/airflow/dags/consumer.py for tasks to queue
[2024-03-27T19:15:20.149+0000] {logging_mixin.py:120} INFO - [2024-03-27T19:15:20.149+0000] {dagbag.py:537} INFO - Filling up the DagBag from /opt/airflow/dags/consumer.py
[2024-03-27T19:15:20.162+0000] {logging_mixin.py:120} INFO - [2024-03-27T19:15:20.161+0000] {dagbag.py:342} ERROR - Failed to import: /opt/airflow/dags/consumer.py
Traceback (most recent call last):
  File "/home/airflow/.local/lib/python3.7/site-packages/airflow/models/dagbag.py", line 338, in parse
    loader.exec_module(new_module)
  File "<frozen importlib._bootstrap_external>", line 728, in exec_module
  File "<frozen importlib._bootstrap>", line 219, in _call_with_frames_removed
  File "/opt/airflow/dags/consumer.py", line 13, in <module>
    catchup=False
TypeError: __init__() got an unexpected keyword argument 'task_id'
[2024-03-27T19:15:20.163+0000] {processor.py:768} WARNING - No viable dags retrieved from /opt/airflow/dags/consumer.py
[2024-03-27T19:15:20.179+0000] {processor.py:176} INFO - Processing /opt/airflow/dags/consumer.py took 0.038 seconds
[2024-03-27T19:15:50.729+0000] {processor.py:154} INFO - Started process (PID=102) to work on /opt/airflow/dags/consumer.py
[2024-03-27T19:15:50.737+0000] {processor.py:756} INFO - Processing file /opt/airflow/dags/consumer.py for tasks to queue
[2024-03-27T19:15:50.738+0000] {logging_mixin.py:120} INFO - [2024-03-27T19:15:50.737+0000] {dagbag.py:537} INFO - Filling up the DagBag from /opt/airflow/dags/consumer.py
[2024-03-27T19:15:50.852+0000] {logging_mixin.py:120} INFO - [2024-03-27T19:15:50.839+0000] {dagbag.py:342} ERROR - Failed to import: /opt/airflow/dags/consumer.py
Traceback (most recent call last):
  File "/home/airflow/.local/lib/python3.7/site-packages/airflow/models/dagbag.py", line 338, in parse
    loader.exec_module(new_module)
  File "<frozen importlib._bootstrap_external>", line 728, in exec_module
  File "<frozen importlib._bootstrap>", line 219, in _call_with_frames_removed
  File "/opt/airflow/dags/consumer.py", line 13, in <module>
    catchup=False
TypeError: __init__() got an unexpected keyword argument 'task_id'
[2024-03-27T19:15:50.866+0000] {processor.py:768} WARNING - No viable dags retrieved from /opt/airflow/dags/consumer.py
[2024-03-27T19:15:51.070+0000] {processor.py:176} INFO - Processing /opt/airflow/dags/consumer.py took 0.359 seconds
[2024-03-27T19:16:21.195+0000] {processor.py:154} INFO - Started process (PID=160) to work on /opt/airflow/dags/consumer.py
[2024-03-27T19:16:21.197+0000] {processor.py:756} INFO - Processing file /opt/airflow/dags/consumer.py for tasks to queue
[2024-03-27T19:16:21.199+0000] {logging_mixin.py:120} INFO - [2024-03-27T19:16:21.199+0000] {dagbag.py:537} INFO - Filling up the DagBag from /opt/airflow/dags/consumer.py
[2024-03-27T19:16:21.291+0000] {logging_mixin.py:120} INFO - [2024-03-27T19:16:21.284+0000] {dagbag.py:342} ERROR - Failed to import: /opt/airflow/dags/consumer.py
Traceback (most recent call last):
  File "/home/airflow/.local/lib/python3.7/site-packages/airflow/models/dagbag.py", line 338, in parse
    loader.exec_module(new_module)
  File "<frozen importlib._bootstrap_external>", line 728, in exec_module
  File "<frozen importlib._bootstrap>", line 219, in _call_with_frames_removed
  File "/opt/airflow/dags/consumer.py", line 13, in <module>
    catchup=False
TypeError: __init__() got an unexpected keyword argument 'task_id'
[2024-03-27T19:16:21.292+0000] {processor.py:768} WARNING - No viable dags retrieved from /opt/airflow/dags/consumer.py
[2024-03-27T19:16:21.398+0000] {processor.py:176} INFO - Processing /opt/airflow/dags/consumer.py took 0.214 seconds
[2024-03-27T19:16:49.184+0000] {processor.py:154} INFO - Started process (PID=42) to work on /opt/airflow/dags/consumer.py
[2024-03-27T19:16:49.188+0000] {processor.py:756} INFO - Processing file /opt/airflow/dags/consumer.py for tasks to queue
[2024-03-27T19:16:49.189+0000] {logging_mixin.py:120} INFO - [2024-03-27T19:16:49.189+0000] {dagbag.py:537} INFO - Filling up the DagBag from /opt/airflow/dags/consumer.py
[2024-03-27T19:16:49.209+0000] {logging_mixin.py:120} INFO - [2024-03-27T19:16:49.208+0000] {dagbag.py:342} ERROR - Failed to import: /opt/airflow/dags/consumer.py
Traceback (most recent call last):
  File "/home/airflow/.local/lib/python3.7/site-packages/airflow/models/dagbag.py", line 338, in parse
    loader.exec_module(new_module)
  File "<frozen importlib._bootstrap_external>", line 728, in exec_module
  File "<frozen importlib._bootstrap>", line 219, in _call_with_frames_removed
  File "/opt/airflow/dags/consumer.py", line 13, in <module>
    catchup=False
TypeError: __init__() got an unexpected keyword argument 'task_id'
[2024-03-27T19:16:49.209+0000] {processor.py:768} WARNING - No viable dags retrieved from /opt/airflow/dags/consumer.py
[2024-03-27T19:16:49.227+0000] {processor.py:176} INFO - Processing /opt/airflow/dags/consumer.py took 0.059 seconds
[2024-03-27T19:17:20.171+0000] {processor.py:154} INFO - Started process (PID=100) to work on /opt/airflow/dags/consumer.py
[2024-03-27T19:17:20.184+0000] {processor.py:756} INFO - Processing file /opt/airflow/dags/consumer.py for tasks to queue
[2024-03-27T19:17:20.190+0000] {logging_mixin.py:120} INFO - [2024-03-27T19:17:20.189+0000] {dagbag.py:537} INFO - Filling up the DagBag from /opt/airflow/dags/consumer.py
[2024-03-27T19:17:20.374+0000] {logging_mixin.py:120} INFO - [2024-03-27T19:17:20.352+0000] {dagbag.py:342} ERROR - Failed to import: /opt/airflow/dags/consumer.py
Traceback (most recent call last):
  File "/home/airflow/.local/lib/python3.7/site-packages/airflow/models/dagbag.py", line 338, in parse
    loader.exec_module(new_module)
  File "<frozen importlib._bootstrap_external>", line 728, in exec_module
  File "<frozen importlib._bootstrap>", line 219, in _call_with_frames_removed
  File "/opt/airflow/dags/consumer.py", line 13, in <module>
    catchup=False
TypeError: __init__() got an unexpected keyword argument 'task_id'
[2024-03-27T19:17:20.378+0000] {processor.py:768} WARNING - No viable dags retrieved from /opt/airflow/dags/consumer.py
[2024-03-27T19:17:22.893+0000] {processor.py:176} INFO - Processing /opt/airflow/dags/consumer.py took 2.736 seconds
[2024-03-27T19:18:18.567+0000] {processor.py:154} INFO - Started process (PID=43) to work on /opt/airflow/dags/consumer.py
[2024-03-27T19:18:18.569+0000] {processor.py:756} INFO - Processing file /opt/airflow/dags/consumer.py for tasks to queue
[2024-03-27T19:18:18.570+0000] {logging_mixin.py:120} INFO - [2024-03-27T19:18:18.570+0000] {dagbag.py:537} INFO - Filling up the DagBag from /opt/airflow/dags/consumer.py
[2024-03-27T19:18:18.595+0000] {logging_mixin.py:120} INFO - [2024-03-27T19:18:18.594+0000] {dagbag.py:342} ERROR - Failed to import: /opt/airflow/dags/consumer.py
Traceback (most recent call last):
  File "/home/airflow/.local/lib/python3.7/site-packages/airflow/models/dagbag.py", line 338, in parse
    loader.exec_module(new_module)
  File "<frozen importlib._bootstrap_external>", line 728, in exec_module
  File "<frozen importlib._bootstrap>", line 219, in _call_with_frames_removed
  File "/opt/airflow/dags/consumer.py", line 13, in <module>
    catchup=False
TypeError: __init__() got an unexpected keyword argument 'task_id'
[2024-03-27T19:18:18.596+0000] {processor.py:768} WARNING - No viable dags retrieved from /opt/airflow/dags/consumer.py
[2024-03-27T19:18:18.620+0000] {processor.py:176} INFO - Processing /opt/airflow/dags/consumer.py took 0.054 seconds
[2024-03-27T19:18:49.082+0000] {processor.py:154} INFO - Started process (PID=101) to work on /opt/airflow/dags/consumer.py
[2024-03-27T19:18:49.085+0000] {processor.py:756} INFO - Processing file /opt/airflow/dags/consumer.py for tasks to queue
[2024-03-27T19:18:49.085+0000] {logging_mixin.py:120} INFO - [2024-03-27T19:18:49.085+0000] {dagbag.py:537} INFO - Filling up the DagBag from /opt/airflow/dags/consumer.py
[2024-03-27T19:18:49.111+0000] {logging_mixin.py:120} INFO - [2024-03-27T19:18:49.110+0000] {dagbag.py:342} ERROR - Failed to import: /opt/airflow/dags/consumer.py
Traceback (most recent call last):
  File "/home/airflow/.local/lib/python3.7/site-packages/airflow/models/dagbag.py", line 338, in parse
    loader.exec_module(new_module)
  File "<frozen importlib._bootstrap_external>", line 728, in exec_module
  File "<frozen importlib._bootstrap>", line 219, in _call_with_frames_removed
  File "/opt/airflow/dags/consumer.py", line 13, in <module>
    catchup=False
TypeError: __init__() got an unexpected keyword argument 'task_id'
[2024-03-27T19:18:49.111+0000] {processor.py:768} WARNING - No viable dags retrieved from /opt/airflow/dags/consumer.py
[2024-03-27T19:18:49.126+0000] {processor.py:176} INFO - Processing /opt/airflow/dags/consumer.py took 0.048 seconds
[2024-03-27T19:19:19.751+0000] {processor.py:154} INFO - Started process (PID=161) to work on /opt/airflow/dags/consumer.py
[2024-03-27T19:19:19.756+0000] {processor.py:756} INFO - Processing file /opt/airflow/dags/consumer.py for tasks to queue
[2024-03-27T19:19:19.775+0000] {logging_mixin.py:120} INFO - [2024-03-27T19:19:19.764+0000] {dagbag.py:537} INFO - Filling up the DagBag from /opt/airflow/dags/consumer.py
[2024-03-27T19:19:40.000+0000] {processor.py:154} INFO - Started process (PID=43) to work on /opt/airflow/dags/consumer.py
[2024-03-27T19:19:40.003+0000] {processor.py:756} INFO - Processing file /opt/airflow/dags/consumer.py for tasks to queue
[2024-03-27T19:19:40.004+0000] {logging_mixin.py:120} INFO - [2024-03-27T19:19:40.004+0000] {dagbag.py:537} INFO - Filling up the DagBag from /opt/airflow/dags/consumer.py
[2024-03-27T19:19:40.018+0000] {logging_mixin.py:120} INFO - [2024-03-27T19:19:40.017+0000] {dagbag.py:342} ERROR - Failed to import: /opt/airflow/dags/consumer.py
Traceback (most recent call last):
  File "/home/airflow/.local/lib/python3.7/site-packages/airflow/models/dagbag.py", line 338, in parse
    loader.exec_module(new_module)
  File "<frozen importlib._bootstrap_external>", line 728, in exec_module
  File "<frozen importlib._bootstrap>", line 219, in _call_with_frames_removed
  File "/opt/airflow/dags/consumer.py", line 13, in <module>
    catchup=False
TypeError: __init__() got an unexpected keyword argument 'task_id'
[2024-03-27T19:19:40.018+0000] {processor.py:768} WARNING - No viable dags retrieved from /opt/airflow/dags/consumer.py
[2024-03-27T19:19:40.032+0000] {processor.py:176} INFO - Processing /opt/airflow/dags/consumer.py took 0.033 seconds
[2024-03-27T19:20:14.992+0000] {processor.py:154} INFO - Started process (PID=102) to work on /opt/airflow/dags/consumer.py
[2024-03-27T19:20:15.003+0000] {processor.py:756} INFO - Processing file /opt/airflow/dags/consumer.py for tasks to queue
[2024-03-27T19:20:15.020+0000] {logging_mixin.py:120} INFO - [2024-03-27T19:20:15.019+0000] {dagbag.py:537} INFO - Filling up the DagBag from /opt/airflow/dags/consumer.py
[2024-03-27T19:20:15.415+0000] {logging_mixin.py:120} INFO - [2024-03-27T19:20:15.361+0000] {dagbag.py:342} ERROR - Failed to import: /opt/airflow/dags/consumer.py
Traceback (most recent call last):
  File "/home/airflow/.local/lib/python3.7/site-packages/airflow/models/dagbag.py", line 338, in parse
    loader.exec_module(new_module)
  File "<frozen importlib._bootstrap_external>", line 728, in exec_module
  File "<frozen importlib._bootstrap>", line 219, in _call_with_frames_removed
  File "/opt/airflow/dags/consumer.py", line 13, in <module>
    catchup=False
TypeError: __init__() got an unexpected keyword argument 'task_id'
[2024-03-27T19:20:15.445+0000] {processor.py:768} WARNING - No viable dags retrieved from /opt/airflow/dags/consumer.py
[2024-03-27T19:20:19.295+0000] {processor.py:176} INFO - Processing /opt/airflow/dags/consumer.py took 4.328 seconds
[2024-03-27T19:21:22.423+0000] {processor.py:154} INFO - Started process (PID=42) to work on /opt/airflow/dags/consumer.py
[2024-03-27T19:21:22.424+0000] {processor.py:756} INFO - Processing file /opt/airflow/dags/consumer.py for tasks to queue
[2024-03-27T19:21:22.424+0000] {logging_mixin.py:120} INFO - [2024-03-27T19:21:22.424+0000] {dagbag.py:537} INFO - Filling up the DagBag from /opt/airflow/dags/consumer.py
[2024-03-27T19:21:22.437+0000] {logging_mixin.py:120} INFO - [2024-03-27T19:21:22.436+0000] {dagbag.py:342} ERROR - Failed to import: /opt/airflow/dags/consumer.py
Traceback (most recent call last):
  File "/home/airflow/.local/lib/python3.7/site-packages/airflow/models/dagbag.py", line 338, in parse
    loader.exec_module(new_module)
  File "<frozen importlib._bootstrap_external>", line 728, in exec_module
  File "<frozen importlib._bootstrap>", line 219, in _call_with_frames_removed
  File "/opt/airflow/dags/consumer.py", line 13, in <module>
    catchup=False
TypeError: __init__() got an unexpected keyword argument 'task_id'
[2024-03-27T19:21:22.437+0000] {processor.py:768} WARNING - No viable dags retrieved from /opt/airflow/dags/consumer.py
[2024-03-27T19:21:22.450+0000] {processor.py:176} INFO - Processing /opt/airflow/dags/consumer.py took 0.029 seconds
[2024-03-27T19:21:53.151+0000] {processor.py:154} INFO - Started process (PID=92) to work on /opt/airflow/dags/consumer.py
[2024-03-27T19:21:53.154+0000] {processor.py:756} INFO - Processing file /opt/airflow/dags/consumer.py for tasks to queue
[2024-03-27T19:21:53.155+0000] {logging_mixin.py:120} INFO - [2024-03-27T19:21:53.155+0000] {dagbag.py:537} INFO - Filling up the DagBag from /opt/airflow/dags/consumer.py
[2024-03-27T19:21:53.165+0000] {logging_mixin.py:120} INFO - [2024-03-27T19:21:53.164+0000] {dagbag.py:342} ERROR - Failed to import: /opt/airflow/dags/consumer.py
Traceback (most recent call last):
  File "/home/airflow/.local/lib/python3.7/site-packages/airflow/models/dagbag.py", line 338, in parse
    loader.exec_module(new_module)
  File "<frozen importlib._bootstrap_external>", line 728, in exec_module
  File "<frozen importlib._bootstrap>", line 219, in _call_with_frames_removed
  File "/opt/airflow/dags/consumer.py", line 13, in <module>
    catchup=False
TypeError: __init__() got an unexpected keyword argument 'task_id'
[2024-03-27T19:21:53.165+0000] {processor.py:768} WARNING - No viable dags retrieved from /opt/airflow/dags/consumer.py
[2024-03-27T19:21:53.176+0000] {processor.py:176} INFO - Processing /opt/airflow/dags/consumer.py took 0.027 seconds
[2024-03-27T19:22:24.084+0000] {processor.py:154} INFO - Started process (PID=152) to work on /opt/airflow/dags/consumer.py
[2024-03-27T19:22:24.104+0000] {processor.py:756} INFO - Processing file /opt/airflow/dags/consumer.py for tasks to queue
[2024-03-27T19:22:24.112+0000] {logging_mixin.py:120} INFO - [2024-03-27T19:22:24.111+0000] {dagbag.py:537} INFO - Filling up the DagBag from /opt/airflow/dags/consumer.py
[2024-03-27T19:22:29.720+0000] {processor.py:154} INFO - Started process (PID=33) to work on /opt/airflow/dags/consumer.py
[2024-03-27T19:22:29.721+0000] {processor.py:756} INFO - Processing file /opt/airflow/dags/consumer.py for tasks to queue
[2024-03-27T19:22:29.724+0000] {logging_mixin.py:120} INFO - [2024-03-27T19:22:29.724+0000] {dagbag.py:537} INFO - Filling up the DagBag from /opt/airflow/dags/consumer.py
[2024-03-27T19:22:29.735+0000] {logging_mixin.py:120} INFO - [2024-03-27T19:22:29.734+0000] {dagbag.py:342} ERROR - Failed to import: /opt/airflow/dags/consumer.py
Traceback (most recent call last):
  File "/home/airflow/.local/lib/python3.7/site-packages/airflow/models/dagbag.py", line 338, in parse
    loader.exec_module(new_module)
  File "<frozen importlib._bootstrap_external>", line 728, in exec_module
  File "<frozen importlib._bootstrap>", line 219, in _call_with_frames_removed
  File "/opt/airflow/dags/consumer.py", line 13, in <module>
    catchup=False
TypeError: __init__() got an unexpected keyword argument 'task_id'
[2024-03-27T19:22:29.736+0000] {processor.py:768} WARNING - No viable dags retrieved from /opt/airflow/dags/consumer.py
[2024-03-27T19:22:29.747+0000] {processor.py:176} INFO - Processing /opt/airflow/dags/consumer.py took 0.029 seconds
[2024-03-27T19:23:00.469+0000] {processor.py:154} INFO - Started process (PID=101) to work on /opt/airflow/dags/consumer.py
[2024-03-27T19:23:00.471+0000] {processor.py:756} INFO - Processing file /opt/airflow/dags/consumer.py for tasks to queue
[2024-03-27T19:23:00.471+0000] {logging_mixin.py:120} INFO - [2024-03-27T19:23:00.471+0000] {dagbag.py:537} INFO - Filling up the DagBag from /opt/airflow/dags/consumer.py
[2024-03-27T19:23:00.487+0000] {logging_mixin.py:120} INFO - [2024-03-27T19:23:00.486+0000] {dagbag.py:342} ERROR - Failed to import: /opt/airflow/dags/consumer.py
Traceback (most recent call last):
  File "/home/airflow/.local/lib/python3.7/site-packages/airflow/models/dagbag.py", line 338, in parse
    loader.exec_module(new_module)
  File "<frozen importlib._bootstrap_external>", line 728, in exec_module
  File "<frozen importlib._bootstrap>", line 219, in _call_with_frames_removed
  File "/opt/airflow/dags/consumer.py", line 13, in <module>
    catchup=False
TypeError: __init__() got an unexpected keyword argument 'task_id'
[2024-03-27T19:23:00.488+0000] {processor.py:768} WARNING - No viable dags retrieved from /opt/airflow/dags/consumer.py
[2024-03-27T19:23:00.500+0000] {processor.py:176} INFO - Processing /opt/airflow/dags/consumer.py took 0.033 seconds
[2024-03-27T19:24:26.423+0000] {processor.py:154} INFO - Started process (PID=160) to work on /opt/airflow/dags/consumer.py
[2024-03-27T19:24:26.428+0000] {processor.py:756} INFO - Processing file /opt/airflow/dags/consumer.py for tasks to queue
[2024-03-27T19:24:26.429+0000] {logging_mixin.py:120} INFO - [2024-03-27T19:24:26.429+0000] {dagbag.py:537} INFO - Filling up the DagBag from /opt/airflow/dags/consumer.py
[2024-03-27T19:24:26.445+0000] {logging_mixin.py:120} INFO - [2024-03-27T19:24:26.444+0000] {dagbag.py:342} ERROR - Failed to import: /opt/airflow/dags/consumer.py
Traceback (most recent call last):
  File "/home/airflow/.local/lib/python3.7/site-packages/airflow/models/dagbag.py", line 338, in parse
    loader.exec_module(new_module)
  File "<frozen importlib._bootstrap_external>", line 728, in exec_module
  File "<frozen importlib._bootstrap>", line 219, in _call_with_frames_removed
  File "/opt/airflow/dags/consumer.py", line 13, in <module>
    catchup=False
TypeError: __init__() got an unexpected keyword argument 'task_id'
[2024-03-27T19:24:26.446+0000] {processor.py:768} WARNING - No viable dags retrieved from /opt/airflow/dags/consumer.py
[2024-03-27T19:24:26.479+0000] {processor.py:176} INFO - Processing /opt/airflow/dags/consumer.py took 0.061 seconds
[2024-03-27T19:24:53.098+0000] {processor.py:154} INFO - Started process (PID=33) to work on /opt/airflow/dags/consumer.py
[2024-03-27T19:24:53.099+0000] {processor.py:756} INFO - Processing file /opt/airflow/dags/consumer.py for tasks to queue
[2024-03-27T19:24:53.100+0000] {logging_mixin.py:120} INFO - [2024-03-27T19:24:53.100+0000] {dagbag.py:537} INFO - Filling up the DagBag from /opt/airflow/dags/consumer.py
[2024-03-27T19:24:53.110+0000] {logging_mixin.py:120} INFO - [2024-03-27T19:24:53.109+0000] {dagbag.py:342} ERROR - Failed to import: /opt/airflow/dags/consumer.py
Traceback (most recent call last):
  File "/home/airflow/.local/lib/python3.7/site-packages/airflow/models/dagbag.py", line 338, in parse
    loader.exec_module(new_module)
  File "<frozen importlib._bootstrap_external>", line 728, in exec_module
  File "<frozen importlib._bootstrap>", line 219, in _call_with_frames_removed
  File "/opt/airflow/dags/consumer.py", line 13, in <module>
    catchup=False
TypeError: __init__() got an unexpected keyword argument 'task_id'
[2024-03-27T19:24:53.111+0000] {processor.py:768} WARNING - No viable dags retrieved from /opt/airflow/dags/consumer.py
[2024-03-27T19:24:53.121+0000] {processor.py:176} INFO - Processing /opt/airflow/dags/consumer.py took 0.026 seconds
[2024-03-27T19:25:23.503+0000] {processor.py:154} INFO - Started process (PID=100) to work on /opt/airflow/dags/consumer.py
[2024-03-27T19:25:23.504+0000] {processor.py:756} INFO - Processing file /opt/airflow/dags/consumer.py for tasks to queue
[2024-03-27T19:25:23.505+0000] {logging_mixin.py:120} INFO - [2024-03-27T19:25:23.505+0000] {dagbag.py:537} INFO - Filling up the DagBag from /opt/airflow/dags/consumer.py
[2024-03-27T19:25:23.527+0000] {logging_mixin.py:120} INFO - [2024-03-27T19:25:23.525+0000] {dagbag.py:342} ERROR - Failed to import: /opt/airflow/dags/consumer.py
Traceback (most recent call last):
  File "/home/airflow/.local/lib/python3.7/site-packages/airflow/models/dagbag.py", line 338, in parse
    loader.exec_module(new_module)
  File "<frozen importlib._bootstrap_external>", line 728, in exec_module
  File "<frozen importlib._bootstrap>", line 219, in _call_with_frames_removed
  File "/opt/airflow/dags/consumer.py", line 13, in <module>
    catchup=False
TypeError: __init__() got an unexpected keyword argument 'task_id'
[2024-03-27T19:25:23.527+0000] {processor.py:768} WARNING - No viable dags retrieved from /opt/airflow/dags/consumer.py
[2024-03-27T19:25:23.541+0000] {processor.py:176} INFO - Processing /opt/airflow/dags/consumer.py took 0.042 seconds
[2024-03-27T19:25:53.632+0000] {processor.py:154} INFO - Started process (PID=169) to work on /opt/airflow/dags/consumer.py
[2024-03-27T19:25:53.632+0000] {processor.py:756} INFO - Processing file /opt/airflow/dags/consumer.py for tasks to queue
[2024-03-27T19:25:53.633+0000] {logging_mixin.py:120} INFO - [2024-03-27T19:25:53.633+0000] {dagbag.py:537} INFO - Filling up the DagBag from /opt/airflow/dags/consumer.py
[2024-03-27T19:25:53.647+0000] {logging_mixin.py:120} INFO - [2024-03-27T19:25:53.646+0000] {dagbag.py:342} ERROR - Failed to import: /opt/airflow/dags/consumer.py
Traceback (most recent call last):
  File "/home/airflow/.local/lib/python3.7/site-packages/airflow/models/dagbag.py", line 338, in parse
    loader.exec_module(new_module)
  File "<frozen importlib._bootstrap_external>", line 728, in exec_module
  File "<frozen importlib._bootstrap>", line 219, in _call_with_frames_removed
  File "/opt/airflow/dags/consumer.py", line 13, in <module>
    catchup=False
TypeError: __init__() got an unexpected keyword argument 'task_id'
[2024-03-27T19:25:53.648+0000] {processor.py:768} WARNING - No viable dags retrieved from /opt/airflow/dags/consumer.py
[2024-03-27T19:25:53.670+0000] {processor.py:176} INFO - Processing /opt/airflow/dags/consumer.py took 0.041 seconds
[2024-03-27T19:26:24.327+0000] {processor.py:154} INFO - Started process (PID=228) to work on /opt/airflow/dags/consumer.py
[2024-03-27T19:26:24.330+0000] {processor.py:756} INFO - Processing file /opt/airflow/dags/consumer.py for tasks to queue
[2024-03-27T19:26:24.332+0000] {logging_mixin.py:120} INFO - [2024-03-27T19:26:24.332+0000] {dagbag.py:537} INFO - Filling up the DagBag from /opt/airflow/dags/consumer.py
[2024-03-27T19:26:24.354+0000] {logging_mixin.py:120} INFO - [2024-03-27T19:26:24.352+0000] {dagbag.py:342} ERROR - Failed to import: /opt/airflow/dags/consumer.py
Traceback (most recent call last):
  File "/home/airflow/.local/lib/python3.7/site-packages/airflow/models/dagbag.py", line 338, in parse
    loader.exec_module(new_module)
  File "<frozen importlib._bootstrap_external>", line 728, in exec_module
  File "<frozen importlib._bootstrap>", line 219, in _call_with_frames_removed
  File "/opt/airflow/dags/consumer.py", line 13, in <module>
    catchup=False
TypeError: __init__() got an unexpected keyword argument 'task_id'
[2024-03-27T19:26:24.354+0000] {processor.py:768} WARNING - No viable dags retrieved from /opt/airflow/dags/consumer.py
[2024-03-27T19:26:24.373+0000] {processor.py:176} INFO - Processing /opt/airflow/dags/consumer.py took 0.052 seconds
[2024-03-27T19:26:31.546+0000] {processor.py:154} INFO - Started process (PID=278) to work on /opt/airflow/dags/consumer.py
[2024-03-27T19:26:31.548+0000] {processor.py:756} INFO - Processing file /opt/airflow/dags/consumer.py for tasks to queue
[2024-03-27T19:26:31.549+0000] {logging_mixin.py:120} INFO - [2024-03-27T19:26:31.549+0000] {dagbag.py:537} INFO - Filling up the DagBag from /opt/airflow/dags/consumer.py
[2024-03-27T19:26:31.572+0000] {logging_mixin.py:120} INFO - [2024-03-27T19:26:31.571+0000] {dagbag.py:342} ERROR - Failed to import: /opt/airflow/dags/consumer.py
Traceback (most recent call last):
  File "/home/airflow/.local/lib/python3.7/site-packages/airflow/models/dagbag.py", line 338, in parse
    loader.exec_module(new_module)
  File "<frozen importlib._bootstrap_external>", line 728, in exec_module
  File "<frozen importlib._bootstrap>", line 219, in _call_with_frames_removed
  File "/opt/airflow/dags/consumer.py", line 13, in <module>
    catchup=False
TypeError: __init__() got an unexpected keyword argument 'task_id'
[2024-03-27T19:26:31.573+0000] {processor.py:768} WARNING - No viable dags retrieved from /opt/airflow/dags/consumer.py
[2024-03-27T19:26:31.587+0000] {processor.py:176} INFO - Processing /opt/airflow/dags/consumer.py took 0.046 seconds
[2024-03-27T19:26:56.187+0000] {processor.py:154} INFO - Started process (PID=33) to work on /opt/airflow/dags/consumer.py
[2024-03-27T19:26:56.188+0000] {processor.py:756} INFO - Processing file /opt/airflow/dags/consumer.py for tasks to queue
[2024-03-27T19:26:56.188+0000] {logging_mixin.py:120} INFO - [2024-03-27T19:26:56.188+0000] {dagbag.py:537} INFO - Filling up the DagBag from /opt/airflow/dags/consumer.py
[2024-03-27T19:26:56.198+0000] {logging_mixin.py:120} INFO - [2024-03-27T19:26:56.197+0000] {dagbag.py:342} ERROR - Failed to import: /opt/airflow/dags/consumer.py
Traceback (most recent call last):
  File "/home/airflow/.local/lib/python3.7/site-packages/airflow/models/dagbag.py", line 338, in parse
    loader.exec_module(new_module)
  File "<frozen importlib._bootstrap_external>", line 728, in exec_module
  File "<frozen importlib._bootstrap>", line 219, in _call_with_frames_removed
  File "/opt/airflow/dags/consumer.py", line 13, in <module>
    catchup=False
TypeError: __init__() got an unexpected keyword argument 'task_id'
[2024-03-27T19:26:56.198+0000] {processor.py:768} WARNING - No viable dags retrieved from /opt/airflow/dags/consumer.py
[2024-03-27T19:26:56.209+0000] {processor.py:176} INFO - Processing /opt/airflow/dags/consumer.py took 0.024 seconds
[2024-03-27T19:27:09.044+0000] {processor.py:154} INFO - Started process (PID=83) to work on /opt/airflow/dags/consumer.py
[2024-03-27T19:27:09.048+0000] {processor.py:756} INFO - Processing file /opt/airflow/dags/consumer.py for tasks to queue
[2024-03-27T19:27:09.049+0000] {logging_mixin.py:120} INFO - [2024-03-27T19:27:09.049+0000] {dagbag.py:537} INFO - Filling up the DagBag from /opt/airflow/dags/consumer.py
[2024-03-27T19:27:09.091+0000] {logging_mixin.py:120} INFO - [2024-03-27T19:27:09.088+0000] {dagbag.py:342} ERROR - Failed to import: /opt/airflow/dags/consumer.py
Traceback (most recent call last):
  File "/home/airflow/.local/lib/python3.7/site-packages/airflow/models/dagbag.py", line 338, in parse
    loader.exec_module(new_module)
  File "<frozen importlib._bootstrap_external>", line 728, in exec_module
  File "<frozen importlib._bootstrap>", line 219, in _call_with_frames_removed
  File "/opt/airflow/dags/consumer.py", line 13, in <module>
    catchup=False
TypeError: __init__() got an unexpected keyword argument 'task_id'
[2024-03-27T19:27:09.092+0000] {processor.py:768} WARNING - No viable dags retrieved from /opt/airflow/dags/consumer.py
[2024-03-27T19:27:09.107+0000] {processor.py:176} INFO - Processing /opt/airflow/dags/consumer.py took 0.070 seconds
[2024-03-27T19:27:39.374+0000] {processor.py:154} INFO - Started process (PID=154) to work on /opt/airflow/dags/consumer.py
[2024-03-27T19:27:39.377+0000] {processor.py:756} INFO - Processing file /opt/airflow/dags/consumer.py for tasks to queue
[2024-03-27T19:27:39.378+0000] {logging_mixin.py:120} INFO - [2024-03-27T19:27:39.378+0000] {dagbag.py:537} INFO - Filling up the DagBag from /opt/airflow/dags/consumer.py
[2024-03-27T19:27:39.399+0000] {logging_mixin.py:120} INFO - [2024-03-27T19:27:39.397+0000] {dagbag.py:342} ERROR - Failed to import: /opt/airflow/dags/consumer.py
Traceback (most recent call last):
  File "/home/airflow/.local/lib/python3.7/site-packages/airflow/models/dagbag.py", line 338, in parse
    loader.exec_module(new_module)
  File "<frozen importlib._bootstrap_external>", line 728, in exec_module
  File "<frozen importlib._bootstrap>", line 219, in _call_with_frames_removed
  File "/opt/airflow/dags/consumer.py", line 13, in <module>
    catchup=False
TypeError: __init__() got an unexpected keyword argument 'task_id'
[2024-03-27T19:27:39.400+0000] {processor.py:768} WARNING - No viable dags retrieved from /opt/airflow/dags/consumer.py
[2024-03-27T19:27:39.417+0000] {processor.py:176} INFO - Processing /opt/airflow/dags/consumer.py took 0.048 seconds
[2024-03-27T19:28:13.948+0000] {processor.py:154} INFO - Started process (PID=218) to work on /opt/airflow/dags/consumer.py
[2024-03-27T19:28:13.951+0000] {processor.py:756} INFO - Processing file /opt/airflow/dags/consumer.py for tasks to queue
[2024-03-27T19:28:13.953+0000] {logging_mixin.py:120} INFO - [2024-03-27T19:28:13.953+0000] {dagbag.py:537} INFO - Filling up the DagBag from /opt/airflow/dags/consumer.py
[2024-03-27T19:28:14.056+0000] {logging_mixin.py:120} INFO - [2024-03-27T19:28:14.051+0000] {dagbag.py:342} ERROR - Failed to import: /opt/airflow/dags/consumer.py
Traceback (most recent call last):
  File "/home/airflow/.local/lib/python3.7/site-packages/airflow/models/dagbag.py", line 338, in parse
    loader.exec_module(new_module)
  File "<frozen importlib._bootstrap_external>", line 728, in exec_module
  File "<frozen importlib._bootstrap>", line 219, in _call_with_frames_removed
  File "/opt/airflow/dags/consumer.py", line 13, in <module>
    catchup=False
TypeError: __init__() got an unexpected keyword argument 'task_id'
[2024-03-27T19:28:14.057+0000] {processor.py:768} WARNING - No viable dags retrieved from /opt/airflow/dags/consumer.py
[2024-03-27T19:28:14.174+0000] {processor.py:176} INFO - Processing /opt/airflow/dags/consumer.py took 0.236 seconds
[2024-03-27T19:28:44.757+0000] {processor.py:154} INFO - Started process (PID=280) to work on /opt/airflow/dags/consumer.py
[2024-03-27T19:28:44.761+0000] {processor.py:756} INFO - Processing file /opt/airflow/dags/consumer.py for tasks to queue
[2024-03-27T19:28:44.769+0000] {logging_mixin.py:120} INFO - [2024-03-27T19:28:44.769+0000] {dagbag.py:537} INFO - Filling up the DagBag from /opt/airflow/dags/consumer.py
[2024-03-27T19:28:44.995+0000] {logging_mixin.py:120} INFO - [2024-03-27T19:28:44.980+0000] {dagbag.py:342} ERROR - Failed to import: /opt/airflow/dags/consumer.py
Traceback (most recent call last):
  File "/home/airflow/.local/lib/python3.7/site-packages/airflow/models/dagbag.py", line 338, in parse
    loader.exec_module(new_module)
  File "<frozen importlib._bootstrap_external>", line 728, in exec_module
  File "<frozen importlib._bootstrap>", line 219, in _call_with_frames_removed
  File "/opt/airflow/dags/consumer.py", line 13, in <module>
    catchup=False
TypeError: __init__() got an unexpected keyword argument 'task_id'
[2024-03-27T19:28:44.998+0000] {processor.py:768} WARNING - No viable dags retrieved from /opt/airflow/dags/consumer.py
[2024-03-27T19:28:45.140+0000] {processor.py:176} INFO - Processing /opt/airflow/dags/consumer.py took 0.402 seconds
[2024-03-27T19:29:15.295+0000] {processor.py:154} INFO - Started process (PID=332) to work on /opt/airflow/dags/consumer.py
[2024-03-27T19:29:15.297+0000] {processor.py:756} INFO - Processing file /opt/airflow/dags/consumer.py for tasks to queue
[2024-03-27T19:29:15.297+0000] {logging_mixin.py:120} INFO - [2024-03-27T19:29:15.297+0000] {dagbag.py:537} INFO - Filling up the DagBag from /opt/airflow/dags/consumer.py
[2024-03-27T19:29:15.314+0000] {logging_mixin.py:120} INFO - [2024-03-27T19:29:15.311+0000] {dagbag.py:342} ERROR - Failed to import: /opt/airflow/dags/consumer.py
Traceback (most recent call last):
  File "/home/airflow/.local/lib/python3.7/site-packages/airflow/models/dagbag.py", line 338, in parse
    loader.exec_module(new_module)
  File "<frozen importlib._bootstrap_external>", line 728, in exec_module
  File "<frozen importlib._bootstrap>", line 219, in _call_with_frames_removed
  File "/opt/airflow/dags/consumer.py", line 13, in <module>
    catchup=False
TypeError: __init__() got an unexpected keyword argument 'task_id'
[2024-03-27T19:29:15.315+0000] {processor.py:768} WARNING - No viable dags retrieved from /opt/airflow/dags/consumer.py
[2024-03-27T19:29:15.337+0000] {processor.py:176} INFO - Processing /opt/airflow/dags/consumer.py took 0.045 seconds
[2024-03-27T19:29:55.522+0000] {processor.py:154} INFO - Started process (PID=381) to work on /opt/airflow/dags/consumer.py
[2024-03-27T19:29:55.527+0000] {processor.py:756} INFO - Processing file /opt/airflow/dags/consumer.py for tasks to queue
[2024-03-27T19:29:55.527+0000] {logging_mixin.py:120} INFO - [2024-03-27T19:29:55.527+0000] {dagbag.py:537} INFO - Filling up the DagBag from /opt/airflow/dags/consumer.py
[2024-03-27T19:29:55.552+0000] {logging_mixin.py:120} INFO - [2024-03-27T19:29:55.550+0000] {dagbag.py:342} ERROR - Failed to import: /opt/airflow/dags/consumer.py
Traceback (most recent call last):
  File "/home/airflow/.local/lib/python3.7/site-packages/airflow/models/dagbag.py", line 338, in parse
    loader.exec_module(new_module)
  File "<frozen importlib._bootstrap_external>", line 728, in exec_module
  File "<frozen importlib._bootstrap>", line 219, in _call_with_frames_removed
  File "/opt/airflow/dags/consumer.py", line 13, in <module>
    catchup=False
TypeError: __init__() got an unexpected keyword argument 'task_id'
[2024-03-27T19:29:55.554+0000] {processor.py:768} WARNING - No viable dags retrieved from /opt/airflow/dags/consumer.py
[2024-03-27T19:29:55.581+0000] {processor.py:176} INFO - Processing /opt/airflow/dags/consumer.py took 0.061 seconds
[2024-03-27T19:30:12.760+0000] {processor.py:154} INFO - Started process (PID=419) to work on /opt/airflow/dags/consumer.py
[2024-03-27T19:30:12.761+0000] {processor.py:756} INFO - Processing file /opt/airflow/dags/consumer.py for tasks to queue
[2024-03-27T19:30:12.762+0000] {logging_mixin.py:120} INFO - [2024-03-27T19:30:12.762+0000] {dagbag.py:537} INFO - Filling up the DagBag from /opt/airflow/dags/consumer.py
[2024-03-27T19:30:12.782+0000] {logging_mixin.py:120} INFO - [2024-03-27T19:30:12.781+0000] {dagbag.py:342} ERROR - Failed to import: /opt/airflow/dags/consumer.py
Traceback (most recent call last):
  File "/home/airflow/.local/lib/python3.7/site-packages/airflow/models/dagbag.py", line 338, in parse
    loader.exec_module(new_module)
  File "<frozen importlib._bootstrap_external>", line 728, in exec_module
  File "<frozen importlib._bootstrap>", line 219, in _call_with_frames_removed
  File "/opt/airflow/dags/consumer.py", line 13, in <module>
    catchup=False
TypeError: __init__() got an unexpected keyword argument 'task_id'
[2024-03-27T19:30:12.783+0000] {processor.py:768} WARNING - No viable dags retrieved from /opt/airflow/dags/consumer.py
[2024-03-27T19:30:12.803+0000] {processor.py:176} INFO - Processing /opt/airflow/dags/consumer.py took 0.048 seconds
[2024-03-27T19:30:18.975+0000] {processor.py:154} INFO - Started process (PID=429) to work on /opt/airflow/dags/consumer.py
[2024-03-27T19:30:18.987+0000] {processor.py:756} INFO - Processing file /opt/airflow/dags/consumer.py for tasks to queue
[2024-03-27T19:30:18.991+0000] {logging_mixin.py:120} INFO - [2024-03-27T19:30:18.991+0000] {dagbag.py:537} INFO - Filling up the DagBag from /opt/airflow/dags/consumer.py
[2024-03-27T19:30:19.318+0000] {logging_mixin.py:120} INFO - [2024-03-27T19:30:19.303+0000] {dagbag.py:342} ERROR - Failed to import: /opt/airflow/dags/consumer.py
Traceback (most recent call last):
  File "/home/airflow/.local/lib/python3.7/site-packages/airflow/models/dagbag.py", line 338, in parse
    loader.exec_module(new_module)
  File "<frozen importlib._bootstrap_external>", line 728, in exec_module
  File "<frozen importlib._bootstrap>", line 219, in _call_with_frames_removed
  File "/opt/airflow/dags/consumer.py", line 13, in <module>
    catchup=False
TypeError: __init__() got an unexpected keyword argument 'task_id'
[2024-03-27T19:30:19.332+0000] {processor.py:768} WARNING - No viable dags retrieved from /opt/airflow/dags/consumer.py
[2024-03-27T19:30:19.698+0000] {processor.py:176} INFO - Processing /opt/airflow/dags/consumer.py took 0.752 seconds
[2024-03-27T19:30:56.211+0000] {processor.py:154} INFO - Started process (PID=480) to work on /opt/airflow/dags/consumer.py
[2024-03-27T19:30:56.215+0000] {processor.py:756} INFO - Processing file /opt/airflow/dags/consumer.py for tasks to queue
[2024-03-27T19:30:56.215+0000] {logging_mixin.py:120} INFO - [2024-03-27T19:30:56.215+0000] {dagbag.py:537} INFO - Filling up the DagBag from /opt/airflow/dags/consumer.py
[2024-03-27T19:30:56.229+0000] {logging_mixin.py:120} INFO - [2024-03-27T19:30:56.225+0000] {dagbag.py:342} ERROR - Failed to import: /opt/airflow/dags/consumer.py
Traceback (most recent call last):
  File "/home/airflow/.local/lib/python3.7/site-packages/airflow/models/dagbag.py", line 338, in parse
    loader.exec_module(new_module)
  File "<frozen importlib._bootstrap_external>", line 728, in exec_module
  File "<frozen importlib._bootstrap>", line 219, in _call_with_frames_removed
  File "/opt/airflow/dags/consumer.py", line 13, in <module>
    catchup=False
TypeError: __init__() got an unexpected keyword argument 'task_id'
[2024-03-27T19:30:56.232+0000] {processor.py:768} WARNING - No viable dags retrieved from /opt/airflow/dags/consumer.py
[2024-03-27T19:30:56.248+0000] {processor.py:176} INFO - Processing /opt/airflow/dags/consumer.py took 0.039 seconds
[2024-03-27T19:31:26.308+0000] {processor.py:154} INFO - Started process (PID=531) to work on /opt/airflow/dags/consumer.py
[2024-03-27T19:31:26.309+0000] {processor.py:756} INFO - Processing file /opt/airflow/dags/consumer.py for tasks to queue
[2024-03-27T19:31:26.309+0000] {logging_mixin.py:120} INFO - [2024-03-27T19:31:26.309+0000] {dagbag.py:537} INFO - Filling up the DagBag from /opt/airflow/dags/consumer.py
[2024-03-27T19:31:26.318+0000] {logging_mixin.py:120} INFO - [2024-03-27T19:31:26.317+0000] {dagbag.py:342} ERROR - Failed to import: /opt/airflow/dags/consumer.py
Traceback (most recent call last):
  File "/home/airflow/.local/lib/python3.7/site-packages/airflow/models/dagbag.py", line 338, in parse
    loader.exec_module(new_module)
  File "<frozen importlib._bootstrap_external>", line 728, in exec_module
  File "<frozen importlib._bootstrap>", line 219, in _call_with_frames_removed
  File "/opt/airflow/dags/consumer.py", line 13, in <module>
    catchup=False
TypeError: __init__() got an unexpected keyword argument 'task_id'
[2024-03-27T19:31:26.318+0000] {processor.py:768} WARNING - No viable dags retrieved from /opt/airflow/dags/consumer.py
[2024-03-27T19:31:26.327+0000] {processor.py:176} INFO - Processing /opt/airflow/dags/consumer.py took 0.021 seconds
[2024-03-27T19:32:01.596+0000] {processor.py:154} INFO - Started process (PID=552) to work on /opt/airflow/dags/consumer.py
[2024-03-27T19:32:01.597+0000] {processor.py:756} INFO - Processing file /opt/airflow/dags/consumer.py for tasks to queue
[2024-03-27T19:32:01.598+0000] {logging_mixin.py:120} INFO - [2024-03-27T19:32:01.598+0000] {dagbag.py:537} INFO - Filling up the DagBag from /opt/airflow/dags/consumer.py
[2024-03-27T19:32:01.609+0000] {logging_mixin.py:120} INFO - [2024-03-27T19:32:01.607+0000] {dagbag.py:342} ERROR - Failed to import: /opt/airflow/dags/consumer.py
Traceback (most recent call last):
  File "/home/airflow/.local/lib/python3.7/site-packages/airflow/models/dagbag.py", line 338, in parse
    loader.exec_module(new_module)
  File "<frozen importlib._bootstrap_external>", line 728, in exec_module
  File "<frozen importlib._bootstrap>", line 219, in _call_with_frames_removed
  File "/opt/airflow/dags/consumer.py", line 13, in <module>
    catchup=False
TypeError: __init__() got an unexpected keyword argument 'task_id'
[2024-03-27T19:32:01.609+0000] {processor.py:768} WARNING - No viable dags retrieved from /opt/airflow/dags/consumer.py
[2024-03-27T19:32:01.628+0000] {processor.py:176} INFO - Processing /opt/airflow/dags/consumer.py took 0.034 seconds
[2024-03-27T19:32:45.145+0000] {processor.py:154} INFO - Started process (PID=605) to work on /opt/airflow/dags/consumer.py
[2024-03-27T19:32:45.150+0000] {processor.py:756} INFO - Processing file /opt/airflow/dags/consumer.py for tasks to queue
[2024-03-27T19:32:45.151+0000] {logging_mixin.py:120} INFO - [2024-03-27T19:32:45.151+0000] {dagbag.py:537} INFO - Filling up the DagBag from /opt/airflow/dags/consumer.py
[2024-03-27T19:32:45.207+0000] {logging_mixin.py:120} INFO - [2024-03-27T19:32:45.194+0000] {dagbag.py:342} ERROR - Failed to import: /opt/airflow/dags/consumer.py
Traceback (most recent call last):
  File "/home/airflow/.local/lib/python3.7/site-packages/airflow/models/dagbag.py", line 338, in parse
    loader.exec_module(new_module)
  File "<frozen importlib._bootstrap_external>", line 728, in exec_module
  File "<frozen importlib._bootstrap>", line 219, in _call_with_frames_removed
  File "/opt/airflow/dags/consumer.py", line 13, in <module>
    catchup=False
TypeError: __init__() got an unexpected keyword argument 'task_id'
[2024-03-27T19:32:45.210+0000] {processor.py:768} WARNING - No viable dags retrieved from /opt/airflow/dags/consumer.py
[2024-03-27T19:32:45.250+0000] {processor.py:176} INFO - Processing /opt/airflow/dags/consumer.py took 0.114 seconds
[2024-03-27T19:33:18.303+0000] {processor.py:154} INFO - Started process (PID=659) to work on /opt/airflow/dags/consumer.py
[2024-03-27T19:33:18.307+0000] {processor.py:756} INFO - Processing file /opt/airflow/dags/consumer.py for tasks to queue
[2024-03-27T19:33:18.307+0000] {logging_mixin.py:120} INFO - [2024-03-27T19:33:18.307+0000] {dagbag.py:537} INFO - Filling up the DagBag from /opt/airflow/dags/consumer.py
[2024-03-27T19:33:18.356+0000] {logging_mixin.py:120} INFO - [2024-03-27T19:33:18.351+0000] {dagbag.py:342} ERROR - Failed to import: /opt/airflow/dags/consumer.py
Traceback (most recent call last):
  File "/home/airflow/.local/lib/python3.7/site-packages/airflow/models/dagbag.py", line 338, in parse
    loader.exec_module(new_module)
  File "<frozen importlib._bootstrap_external>", line 728, in exec_module
  File "<frozen importlib._bootstrap>", line 219, in _call_with_frames_removed
  File "/opt/airflow/dags/consumer.py", line 13, in <module>
    catchup=False
TypeError: __init__() got an unexpected keyword argument 'task_id'
[2024-03-27T19:33:18.358+0000] {processor.py:768} WARNING - No viable dags retrieved from /opt/airflow/dags/consumer.py
[2024-03-27T19:33:18.442+0000] {processor.py:176} INFO - Processing /opt/airflow/dags/consumer.py took 0.144 seconds
[2024-03-27T19:33:48.622+0000] {processor.py:154} INFO - Started process (PID=719) to work on /opt/airflow/dags/consumer.py
[2024-03-27T19:33:48.622+0000] {processor.py:756} INFO - Processing file /opt/airflow/dags/consumer.py for tasks to queue
[2024-03-27T19:33:48.623+0000] {logging_mixin.py:120} INFO - [2024-03-27T19:33:48.623+0000] {dagbag.py:537} INFO - Filling up the DagBag from /opt/airflow/dags/consumer.py
[2024-03-27T19:33:48.634+0000] {logging_mixin.py:120} INFO - [2024-03-27T19:33:48.633+0000] {dagbag.py:342} ERROR - Failed to import: /opt/airflow/dags/consumer.py
Traceback (most recent call last):
  File "/home/airflow/.local/lib/python3.7/site-packages/airflow/models/dagbag.py", line 338, in parse
    loader.exec_module(new_module)
  File "<frozen importlib._bootstrap_external>", line 728, in exec_module
  File "<frozen importlib._bootstrap>", line 219, in _call_with_frames_removed
  File "/opt/airflow/dags/consumer.py", line 13, in <module>
    catchup=False
TypeError: __init__() got an unexpected keyword argument 'task_id'
[2024-03-27T19:33:48.634+0000] {processor.py:768} WARNING - No viable dags retrieved from /opt/airflow/dags/consumer.py
[2024-03-27T19:33:48.645+0000] {processor.py:176} INFO - Processing /opt/airflow/dags/consumer.py took 0.026 seconds
[2024-03-27T19:34:19.473+0000] {processor.py:154} INFO - Started process (PID=771) to work on /opt/airflow/dags/consumer.py
[2024-03-27T19:34:19.478+0000] {processor.py:756} INFO - Processing file /opt/airflow/dags/consumer.py for tasks to queue
[2024-03-27T19:34:19.483+0000] {logging_mixin.py:120} INFO - [2024-03-27T19:34:19.481+0000] {dagbag.py:537} INFO - Filling up the DagBag from /opt/airflow/dags/consumer.py
[2024-03-27T19:34:19.570+0000] {logging_mixin.py:120} INFO - [2024-03-27T19:34:19.558+0000] {dagbag.py:342} ERROR - Failed to import: /opt/airflow/dags/consumer.py
Traceback (most recent call last):
  File "/home/airflow/.local/lib/python3.7/site-packages/airflow/models/dagbag.py", line 338, in parse
    loader.exec_module(new_module)
  File "<frozen importlib._bootstrap_external>", line 728, in exec_module
  File "<frozen importlib._bootstrap>", line 219, in _call_with_frames_removed
  File "/opt/airflow/dags/consumer.py", line 13, in <module>
    catchup=False
TypeError: __init__() got an unexpected keyword argument 'task_id'
[2024-03-27T19:34:19.574+0000] {processor.py:768} WARNING - No viable dags retrieved from /opt/airflow/dags/consumer.py
[2024-03-27T19:34:19.638+0000] {processor.py:176} INFO - Processing /opt/airflow/dags/consumer.py took 0.184 seconds
[2024-03-27T19:34:38.783+0000] {processor.py:154} INFO - Started process (PID=794) to work on /opt/airflow/dags/consumer.py
[2024-03-27T19:34:38.784+0000] {processor.py:756} INFO - Processing file /opt/airflow/dags/consumer.py for tasks to queue
[2024-03-27T19:34:38.785+0000] {logging_mixin.py:120} INFO - [2024-03-27T19:34:38.785+0000] {dagbag.py:537} INFO - Filling up the DagBag from /opt/airflow/dags/consumer.py
[2024-03-27T19:34:38.805+0000] {logging_mixin.py:120} INFO - [2024-03-27T19:34:38.802+0000] {dagbag.py:342} ERROR - Failed to import: /opt/airflow/dags/consumer.py
Traceback (most recent call last):
  File "/home/airflow/.local/lib/python3.7/site-packages/airflow/models/dagbag.py", line 338, in parse
    loader.exec_module(new_module)
  File "<frozen importlib._bootstrap_external>", line 728, in exec_module
  File "<frozen importlib._bootstrap>", line 219, in _call_with_frames_removed
  File "/opt/airflow/dags/consumer.py", line 13, in <module>
    catchup=False
TypeError: __init__() got an unexpected keyword argument 'task_id'
[2024-03-27T19:34:38.806+0000] {processor.py:768} WARNING - No viable dags retrieved from /opt/airflow/dags/consumer.py
[2024-03-27T19:34:38.828+0000] {processor.py:176} INFO - Processing /opt/airflow/dags/consumer.py took 0.048 seconds
[2024-03-27T19:35:18.159+0000] {processor.py:154} INFO - Started process (PID=853) to work on /opt/airflow/dags/consumer.py
[2024-03-27T19:35:18.161+0000] {processor.py:756} INFO - Processing file /opt/airflow/dags/consumer.py for tasks to queue
[2024-03-27T19:35:18.164+0000] {logging_mixin.py:120} INFO - [2024-03-27T19:35:18.164+0000] {dagbag.py:537} INFO - Filling up the DagBag from /opt/airflow/dags/consumer.py
[2024-03-27T19:35:18.196+0000] {logging_mixin.py:120} INFO - [2024-03-27T19:35:18.191+0000] {dagbag.py:342} ERROR - Failed to import: /opt/airflow/dags/consumer.py
Traceback (most recent call last):
  File "/home/airflow/.local/lib/python3.7/site-packages/airflow/models/dagbag.py", line 338, in parse
    loader.exec_module(new_module)
  File "<frozen importlib._bootstrap_external>", line 728, in exec_module
  File "<frozen importlib._bootstrap>", line 219, in _call_with_frames_removed
  File "/opt/airflow/dags/consumer.py", line 13, in <module>
    catchup=False
TypeError: __init__() got an unexpected keyword argument 'task_id'
[2024-03-27T19:35:18.197+0000] {processor.py:768} WARNING - No viable dags retrieved from /opt/airflow/dags/consumer.py
[2024-03-27T19:35:18.226+0000] {processor.py:176} INFO - Processing /opt/airflow/dags/consumer.py took 0.073 seconds
[2024-03-27T19:36:10.627+0000] {processor.py:154} INFO - Started process (PID=913) to work on /opt/airflow/dags/consumer.py
[2024-03-27T19:36:10.657+0000] {processor.py:756} INFO - Processing file /opt/airflow/dags/consumer.py for tasks to queue
[2024-03-27T19:36:10.661+0000] {logging_mixin.py:120} INFO - [2024-03-27T19:36:10.660+0000] {dagbag.py:537} INFO - Filling up the DagBag from /opt/airflow/dags/consumer.py
[2024-03-27T19:36:10.728+0000] {logging_mixin.py:120} INFO - [2024-03-27T19:36:10.719+0000] {dagbag.py:342} ERROR - Failed to import: /opt/airflow/dags/consumer.py
Traceback (most recent call last):
  File "/home/airflow/.local/lib/python3.7/site-packages/airflow/models/dagbag.py", line 338, in parse
    loader.exec_module(new_module)
  File "<frozen importlib._bootstrap_external>", line 728, in exec_module
  File "<frozen importlib._bootstrap>", line 219, in _call_with_frames_removed
  File "/opt/airflow/dags/consumer.py", line 13, in <module>
    catchup=False
TypeError: __init__() got an unexpected keyword argument 'task_id'
[2024-03-27T19:36:10.734+0000] {processor.py:768} WARNING - No viable dags retrieved from /opt/airflow/dags/consumer.py
[2024-03-27T19:36:10.841+0000] {processor.py:176} INFO - Processing /opt/airflow/dags/consumer.py took 0.228 seconds
[2024-03-27T19:36:47.451+0000] {processor.py:154} INFO - Started process (PID=33) to work on /opt/airflow/dags/consumer.py
[2024-03-27T19:36:47.456+0000] {processor.py:756} INFO - Processing file /opt/airflow/dags/consumer.py for tasks to queue
[2024-03-27T19:36:47.461+0000] {logging_mixin.py:120} INFO - [2024-03-27T19:36:47.460+0000] {dagbag.py:537} INFO - Filling up the DagBag from /opt/airflow/dags/consumer.py
[2024-03-27T19:36:47.532+0000] {logging_mixin.py:120} INFO - [2024-03-27T19:36:47.528+0000] {dagbag.py:342} ERROR - Failed to import: /opt/airflow/dags/consumer.py
Traceback (most recent call last):
  File "/home/airflow/.local/lib/python3.7/site-packages/airflow/models/dagbag.py", line 338, in parse
    loader.exec_module(new_module)
  File "<frozen importlib._bootstrap_external>", line 728, in exec_module
  File "<frozen importlib._bootstrap>", line 219, in _call_with_frames_removed
  File "/opt/airflow/dags/consumer.py", line 13, in <module>
    catchup=False
TypeError: __init__() got an unexpected keyword argument 'task_id'
[2024-03-27T19:36:47.533+0000] {processor.py:768} WARNING - No viable dags retrieved from /opt/airflow/dags/consumer.py
[2024-03-27T19:36:47.573+0000] {processor.py:176} INFO - Processing /opt/airflow/dags/consumer.py took 0.129 seconds
[2024-03-27T19:37:15.560+0000] {processor.py:154} INFO - Started process (PID=83) to work on /opt/airflow/dags/consumer.py
[2024-03-27T19:37:15.564+0000] {processor.py:756} INFO - Processing file /opt/airflow/dags/consumer.py for tasks to queue
[2024-03-27T19:37:15.566+0000] {logging_mixin.py:120} INFO - [2024-03-27T19:37:15.566+0000] {dagbag.py:537} INFO - Filling up the DagBag from /opt/airflow/dags/consumer.py
[2024-03-27T19:37:15.582+0000] {logging_mixin.py:120} INFO - [2024-03-27T19:37:15.581+0000] {dagbag.py:342} ERROR - Failed to import: /opt/airflow/dags/consumer.py
Traceback (most recent call last):
  File "/home/airflow/.local/lib/python3.7/site-packages/airflow/models/dagbag.py", line 338, in parse
    loader.exec_module(new_module)
  File "<frozen importlib._bootstrap_external>", line 728, in exec_module
  File "<frozen importlib._bootstrap>", line 219, in _call_with_frames_removed
  File "/opt/airflow/dags/consumer.py", line 13, in <module>
    catchup=False
TypeError: __init__() got an unexpected keyword argument 'task_id'
[2024-03-27T19:37:15.583+0000] {processor.py:768} WARNING - No viable dags retrieved from /opt/airflow/dags/consumer.py
[2024-03-27T19:37:15.608+0000] {processor.py:176} INFO - Processing /opt/airflow/dags/consumer.py took 0.051 seconds
[2024-03-27T19:37:45.293+0000] {processor.py:154} INFO - Started process (PID=127) to work on /opt/airflow/dags/consumer.py
[2024-03-27T19:37:45.299+0000] {processor.py:756} INFO - Processing file /opt/airflow/dags/consumer.py for tasks to queue
[2024-03-27T19:37:45.303+0000] {logging_mixin.py:120} INFO - [2024-03-27T19:37:45.303+0000] {dagbag.py:537} INFO - Filling up the DagBag from /opt/airflow/dags/consumer.py
[2024-03-27T19:37:45.372+0000] {logging_mixin.py:120} INFO - [2024-03-27T19:37:45.365+0000] {dagbag.py:342} ERROR - Failed to import: /opt/airflow/dags/consumer.py
Traceback (most recent call last):
  File "/home/airflow/.local/lib/python3.7/site-packages/airflow/models/dagbag.py", line 338, in parse
    loader.exec_module(new_module)
  File "<frozen importlib._bootstrap_external>", line 728, in exec_module
  File "<frozen importlib._bootstrap>", line 219, in _call_with_frames_removed
  File "/opt/airflow/dags/consumer.py", line 13, in <module>
    catchup=False
TypeError: __init__() got an unexpected keyword argument 'task_id'
[2024-03-27T19:37:45.372+0000] {processor.py:768} WARNING - No viable dags retrieved from /opt/airflow/dags/consumer.py
[2024-03-27T19:37:45.417+0000] {processor.py:176} INFO - Processing /opt/airflow/dags/consumer.py took 0.140 seconds
[2024-03-27T19:37:54.495+0000] {processor.py:154} INFO - Started process (PID=33) to work on /opt/airflow/dags/consumer.py
[2024-03-27T19:37:54.497+0000] {processor.py:756} INFO - Processing file /opt/airflow/dags/consumer.py for tasks to queue
[2024-03-27T19:37:54.497+0000] {logging_mixin.py:120} INFO - [2024-03-27T19:37:54.497+0000] {dagbag.py:537} INFO - Filling up the DagBag from /opt/airflow/dags/consumer.py
[2024-03-27T19:37:54.519+0000] {logging_mixin.py:120} INFO - [2024-03-27T19:37:54.515+0000] {dagbag.py:342} ERROR - Failed to import: /opt/airflow/dags/consumer.py
Traceback (most recent call last):
  File "/home/airflow/.local/lib/python3.7/site-packages/airflow/models/dagbag.py", line 338, in parse
    loader.exec_module(new_module)
  File "<frozen importlib._bootstrap_external>", line 728, in exec_module
  File "<frozen importlib._bootstrap>", line 219, in _call_with_frames_removed
  File "/opt/airflow/dags/consumer.py", line 13, in <module>
    catchup=False
TypeError: __init__() got an unexpected keyword argument 'task_id'
[2024-03-27T19:37:54.524+0000] {processor.py:768} WARNING - No viable dags retrieved from /opt/airflow/dags/consumer.py
[2024-03-27T19:37:54.571+0000] {processor.py:176} INFO - Processing /opt/airflow/dags/consumer.py took 0.075 seconds
[2024-03-27T19:38:29.810+0000] {processor.py:154} INFO - Started process (PID=82) to work on /opt/airflow/dags/consumer.py
[2024-03-27T19:38:29.811+0000] {processor.py:756} INFO - Processing file /opt/airflow/dags/consumer.py for tasks to queue
[2024-03-27T19:38:29.812+0000] {logging_mixin.py:120} INFO - [2024-03-27T19:38:29.812+0000] {dagbag.py:537} INFO - Filling up the DagBag from /opt/airflow/dags/consumer.py
[2024-03-27T19:38:29.836+0000] {logging_mixin.py:120} INFO - [2024-03-27T19:38:29.836+0000] {dagbag.py:342} ERROR - Failed to import: /opt/airflow/dags/consumer.py
Traceback (most recent call last):
  File "/home/airflow/.local/lib/python3.7/site-packages/airflow/models/dagbag.py", line 338, in parse
    loader.exec_module(new_module)
  File "<frozen importlib._bootstrap_external>", line 728, in exec_module
  File "<frozen importlib._bootstrap>", line 219, in _call_with_frames_removed
  File "/opt/airflow/dags/consumer.py", line 13, in <module>
    catchup=False
TypeError: __init__() got an unexpected keyword argument 'task_id'
[2024-03-27T19:38:29.837+0000] {processor.py:768} WARNING - No viable dags retrieved from /opt/airflow/dags/consumer.py
[2024-03-27T19:38:29.855+0000] {processor.py:176} INFO - Processing /opt/airflow/dags/consumer.py took 0.048 seconds
[2024-03-27T19:39:49.648+0000] {processor.py:154} INFO - Started process (PID=51) to work on /opt/airflow/dags/consumer.py
[2024-03-27T19:39:49.655+0000] {processor.py:756} INFO - Processing file /opt/airflow/dags/consumer.py for tasks to queue
[2024-03-27T19:39:49.659+0000] {logging_mixin.py:120} INFO - [2024-03-27T19:39:49.659+0000] {dagbag.py:537} INFO - Filling up the DagBag from /opt/airflow/dags/consumer.py
[2024-03-27T19:39:49.725+0000] {logging_mixin.py:120} INFO - [2024-03-27T19:39:49.721+0000] {dagbag.py:342} ERROR - Failed to import: /opt/airflow/dags/consumer.py
Traceback (most recent call last):
  File "/home/airflow/.local/lib/python3.7/site-packages/airflow/models/dagbag.py", line 338, in parse
    loader.exec_module(new_module)
  File "<frozen importlib._bootstrap_external>", line 728, in exec_module
  File "<frozen importlib._bootstrap>", line 219, in _call_with_frames_removed
  File "/opt/airflow/dags/consumer.py", line 13, in <module>
    catchup=False
TypeError: __init__() got an unexpected keyword argument 'task_id'
[2024-03-27T19:39:49.726+0000] {processor.py:768} WARNING - No viable dags retrieved from /opt/airflow/dags/consumer.py
[2024-03-27T19:39:49.773+0000] {processor.py:176} INFO - Processing /opt/airflow/dags/consumer.py took 0.136 seconds
[2024-03-27T19:40:22.901+0000] {processor.py:154} INFO - Started process (PID=107) to work on /opt/airflow/dags/consumer.py
[2024-03-27T19:40:22.908+0000] {processor.py:756} INFO - Processing file /opt/airflow/dags/consumer.py for tasks to queue
[2024-03-27T19:40:22.916+0000] {logging_mixin.py:120} INFO - [2024-03-27T19:40:22.916+0000] {dagbag.py:537} INFO - Filling up the DagBag from /opt/airflow/dags/consumer.py
[2024-03-27T19:40:23.162+0000] {logging_mixin.py:120} INFO - [2024-03-27T19:40:23.108+0000] {dagbag.py:342} ERROR - Failed to import: /opt/airflow/dags/consumer.py
Traceback (most recent call last):
  File "/home/airflow/.local/lib/python3.7/site-packages/airflow/models/dagbag.py", line 338, in parse
    loader.exec_module(new_module)
  File "<frozen importlib._bootstrap_external>", line 728, in exec_module
  File "<frozen importlib._bootstrap>", line 219, in _call_with_frames_removed
  File "/opt/airflow/dags/consumer.py", line 13, in <module>
    catchup=False
TypeError: __init__() got an unexpected keyword argument 'task_id'
[2024-03-27T19:40:23.191+0000] {processor.py:768} WARNING - No viable dags retrieved from /opt/airflow/dags/consumer.py
[2024-03-27T19:40:24.267+0000] {processor.py:176} INFO - Processing /opt/airflow/dags/consumer.py took 1.406 seconds
[2024-03-27T19:40:58.667+0000] {processor.py:154} INFO - Started process (PID=159) to work on /opt/airflow/dags/consumer.py
[2024-03-27T19:40:58.679+0000] {processor.py:756} INFO - Processing file /opt/airflow/dags/consumer.py for tasks to queue
[2024-03-27T19:40:58.693+0000] {logging_mixin.py:120} INFO - [2024-03-27T19:40:58.687+0000] {dagbag.py:537} INFO - Filling up the DagBag from /opt/airflow/dags/consumer.py
[2024-03-27T19:40:58.780+0000] {logging_mixin.py:120} INFO - [2024-03-27T19:40:58.775+0000] {dagbag.py:342} ERROR - Failed to import: /opt/airflow/dags/consumer.py
Traceback (most recent call last):
  File "/home/airflow/.local/lib/python3.7/site-packages/airflow/models/dagbag.py", line 338, in parse
    loader.exec_module(new_module)
  File "<frozen importlib._bootstrap_external>", line 728, in exec_module
  File "<frozen importlib._bootstrap>", line 219, in _call_with_frames_removed
  File "/opt/airflow/dags/consumer.py", line 13, in <module>
    catchup=False
TypeError: __init__() got an unexpected keyword argument 'task_id'
[2024-03-27T19:40:58.780+0000] {processor.py:768} WARNING - No viable dags retrieved from /opt/airflow/dags/consumer.py
[2024-03-27T19:40:58.896+0000] {processor.py:176} INFO - Processing /opt/airflow/dags/consumer.py took 0.253 seconds
[2024-03-27T19:41:38.393+0000] {processor.py:154} INFO - Started process (PID=41) to work on /opt/airflow/dags/consumer.py
[2024-03-27T19:41:38.397+0000] {processor.py:756} INFO - Processing file /opt/airflow/dags/consumer.py for tasks to queue
[2024-03-27T19:41:38.399+0000] {logging_mixin.py:120} INFO - [2024-03-27T19:41:38.399+0000] {dagbag.py:537} INFO - Filling up the DagBag from /opt/airflow/dags/consumer.py
[2024-03-27T19:41:38.415+0000] {logging_mixin.py:120} INFO - [2024-03-27T19:41:38.413+0000] {dagbag.py:342} ERROR - Failed to import: /opt/airflow/dags/consumer.py
Traceback (most recent call last):
  File "/home/airflow/.local/lib/python3.7/site-packages/airflow/models/dagbag.py", line 338, in parse
    loader.exec_module(new_module)
  File "<frozen importlib._bootstrap_external>", line 728, in exec_module
  File "<frozen importlib._bootstrap>", line 219, in _call_with_frames_removed
  File "/opt/airflow/dags/consumer.py", line 13, in <module>
    catchup=False
TypeError: __init__() got an unexpected keyword argument 'task_id'
[2024-03-27T19:41:38.415+0000] {processor.py:768} WARNING - No viable dags retrieved from /opt/airflow/dags/consumer.py
[2024-03-27T19:41:38.431+0000] {processor.py:176} INFO - Processing /opt/airflow/dags/consumer.py took 0.042 seconds
[2024-03-27T19:42:09.229+0000] {processor.py:154} INFO - Started process (PID=91) to work on /opt/airflow/dags/consumer.py
[2024-03-27T19:42:09.230+0000] {processor.py:756} INFO - Processing file /opt/airflow/dags/consumer.py for tasks to queue
[2024-03-27T19:42:09.232+0000] {logging_mixin.py:120} INFO - [2024-03-27T19:42:09.231+0000] {dagbag.py:537} INFO - Filling up the DagBag from /opt/airflow/dags/consumer.py
[2024-03-27T19:42:09.282+0000] {logging_mixin.py:120} INFO - [2024-03-27T19:42:09.278+0000] {dagbag.py:342} ERROR - Failed to import: /opt/airflow/dags/consumer.py
Traceback (most recent call last):
  File "/home/airflow/.local/lib/python3.7/site-packages/airflow/models/dagbag.py", line 338, in parse
    loader.exec_module(new_module)
  File "<frozen importlib._bootstrap_external>", line 728, in exec_module
  File "<frozen importlib._bootstrap>", line 219, in _call_with_frames_removed
  File "/opt/airflow/dags/consumer.py", line 13, in <module>
    catchup=False
TypeError: __init__() got an unexpected keyword argument 'task_id'
[2024-03-27T19:42:09.283+0000] {processor.py:768} WARNING - No viable dags retrieved from /opt/airflow/dags/consumer.py
[2024-03-27T19:42:09.321+0000] {processor.py:176} INFO - Processing /opt/airflow/dags/consumer.py took 0.101 seconds
[2024-03-27T19:42:45.194+0000] {processor.py:154} INFO - Started process (PID=141) to work on /opt/airflow/dags/consumer.py
[2024-03-27T19:42:45.197+0000] {processor.py:756} INFO - Processing file /opt/airflow/dags/consumer.py for tasks to queue
[2024-03-27T19:42:45.199+0000] {logging_mixin.py:120} INFO - [2024-03-27T19:42:45.198+0000] {dagbag.py:537} INFO - Filling up the DagBag from /opt/airflow/dags/consumer.py
[2024-03-27T19:42:45.318+0000] {logging_mixin.py:120} INFO - [2024-03-27T19:42:45.306+0000] {dagbag.py:342} ERROR - Failed to import: /opt/airflow/dags/consumer.py
Traceback (most recent call last):
  File "/home/airflow/.local/lib/python3.7/site-packages/airflow/models/dagbag.py", line 338, in parse
    loader.exec_module(new_module)
  File "<frozen importlib._bootstrap_external>", line 728, in exec_module
  File "<frozen importlib._bootstrap>", line 219, in _call_with_frames_removed
  File "/opt/airflow/dags/consumer.py", line 13, in <module>
    catchup=False
TypeError: __init__() got an unexpected keyword argument 'task_id'
[2024-03-27T19:42:45.321+0000] {processor.py:768} WARNING - No viable dags retrieved from /opt/airflow/dags/consumer.py
[2024-03-27T19:42:45.508+0000] {processor.py:176} INFO - Processing /opt/airflow/dags/consumer.py took 0.332 seconds
[2024-03-27T19:44:24.734+0000] {processor.py:154} INFO - Started process (PID=43) to work on /opt/airflow/dags/consumer.py
[2024-03-27T19:44:24.741+0000] {processor.py:756} INFO - Processing file /opt/airflow/dags/consumer.py for tasks to queue
[2024-03-27T19:44:24.742+0000] {logging_mixin.py:120} INFO - [2024-03-27T19:44:24.742+0000] {dagbag.py:537} INFO - Filling up the DagBag from /opt/airflow/dags/consumer.py
[2024-03-27T19:44:24.790+0000] {processor.py:766} INFO - DAG(s) dict_keys(['consumer_test']) retrieved from /opt/airflow/dags/consumer.py
[2024-03-27T19:44:25.040+0000] {logging_mixin.py:120} INFO - [2024-03-27T19:44:25.040+0000] {manager.py:507} INFO - Created Permission View: can edit on DAG:consumer_test
[2024-03-27T19:44:25.057+0000] {logging_mixin.py:120} INFO - [2024-03-27T19:44:25.057+0000] {manager.py:507} INFO - Created Permission View: can delete on DAG:consumer_test
[2024-03-27T19:44:25.067+0000] {logging_mixin.py:120} INFO - [2024-03-27T19:44:25.067+0000] {manager.py:507} INFO - Created Permission View: can read on DAG:consumer_test
[2024-03-27T19:44:25.068+0000] {logging_mixin.py:120} INFO - [2024-03-27T19:44:25.068+0000] {dag.py:2585} INFO - Sync 1 DAGs
[2024-03-27T19:44:25.091+0000] {logging_mixin.py:120} INFO - [2024-03-27T19:44:25.091+0000] {dag.py:2606} INFO - Creating ORM DAG for consumer_test
[2024-03-27T19:44:25.122+0000] {logging_mixin.py:120} INFO - [2024-03-27T19:44:25.122+0000] {dag.py:3340} INFO - Setting next_dagrun for consumer_test to None, run_after=None
[2024-03-27T19:44:25.166+0000] {processor.py:176} INFO - Processing /opt/airflow/dags/consumer.py took 0.439 seconds
[2024-03-27T19:44:55.357+0000] {processor.py:154} INFO - Started process (PID=93) to work on /opt/airflow/dags/consumer.py
[2024-03-27T19:44:55.359+0000] {processor.py:756} INFO - Processing file /opt/airflow/dags/consumer.py for tasks to queue
[2024-03-27T19:44:55.361+0000] {logging_mixin.py:120} INFO - [2024-03-27T19:44:55.361+0000] {dagbag.py:537} INFO - Filling up the DagBag from /opt/airflow/dags/consumer.py
[2024-03-27T19:44:55.564+0000] {processor.py:766} INFO - DAG(s) dict_keys(['consumer_test']) retrieved from /opt/airflow/dags/consumer.py
[2024-03-27T19:45:17.924+0000] {logging_mixin.py:120} INFO - [2024-03-27T19:45:17.915+0000] {dag.py:2585} INFO - Sync 1 DAGs
[2024-03-27T19:45:18.073+0000] {logging_mixin.py:120} INFO - [2024-03-27T19:45:18.072+0000] {dag.py:3340} INFO - Setting next_dagrun for consumer_test to None, run_after=None
[2024-03-27T19:45:18.144+0000] {processor.py:176} INFO - Processing /opt/airflow/dags/consumer.py took 22.797 seconds
[2024-03-27T19:46:13.580+0000] {processor.py:154} INFO - Started process (PID=42) to work on /opt/airflow/dags/consumer.py
[2024-03-27T19:46:13.583+0000] {processor.py:756} INFO - Processing file /opt/airflow/dags/consumer.py for tasks to queue
[2024-03-27T19:46:13.584+0000] {logging_mixin.py:120} INFO - [2024-03-27T19:46:13.584+0000] {dagbag.py:537} INFO - Filling up the DagBag from /opt/airflow/dags/consumer.py
[2024-03-27T19:46:13.611+0000] {processor.py:766} INFO - DAG(s) dict_keys(['consumer_test']) retrieved from /opt/airflow/dags/consumer.py
[2024-03-27T19:46:13.654+0000] {logging_mixin.py:120} INFO - [2024-03-27T19:46:13.654+0000] {dag.py:2585} INFO - Sync 1 DAGs
[2024-03-27T19:46:13.672+0000] {logging_mixin.py:120} INFO - [2024-03-27T19:46:13.672+0000] {dag.py:3340} INFO - Setting next_dagrun for consumer_test to None, run_after=None
[2024-03-27T19:46:13.695+0000] {processor.py:176} INFO - Processing /opt/airflow/dags/consumer.py took 0.117 seconds
[2024-03-27T19:46:44.067+0000] {processor.py:154} INFO - Started process (PID=96) to work on /opt/airflow/dags/consumer.py
[2024-03-27T19:46:44.070+0000] {processor.py:756} INFO - Processing file /opt/airflow/dags/consumer.py for tasks to queue
[2024-03-27T19:46:44.071+0000] {logging_mixin.py:120} INFO - [2024-03-27T19:46:44.070+0000] {dagbag.py:537} INFO - Filling up the DagBag from /opt/airflow/dags/consumer.py
[2024-03-27T19:46:44.088+0000] {processor.py:766} INFO - DAG(s) dict_keys(['consumer_test']) retrieved from /opt/airflow/dags/consumer.py
[2024-03-27T19:46:44.116+0000] {logging_mixin.py:120} INFO - [2024-03-27T19:46:44.116+0000] {dag.py:2585} INFO - Sync 1 DAGs
[2024-03-27T19:46:44.130+0000] {logging_mixin.py:120} INFO - [2024-03-27T19:46:44.130+0000] {dag.py:3340} INFO - Setting next_dagrun for consumer_test to None, run_after=None
[2024-03-27T19:46:44.142+0000] {processor.py:176} INFO - Processing /opt/airflow/dags/consumer.py took 0.077 seconds
[2024-03-27T19:47:23.092+0000] {processor.py:154} INFO - Started process (PID=120) to work on /opt/airflow/dags/consumer.py
[2024-03-27T19:47:23.093+0000] {processor.py:756} INFO - Processing file /opt/airflow/dags/consumer.py for tasks to queue
[2024-03-27T19:47:23.093+0000] {logging_mixin.py:120} INFO - [2024-03-27T19:47:23.093+0000] {dagbag.py:537} INFO - Filling up the DagBag from /opt/airflow/dags/consumer.py
[2024-03-27T19:47:23.109+0000] {processor.py:766} INFO - DAG(s) dict_keys(['consumer_test']) retrieved from /opt/airflow/dags/consumer.py
[2024-03-27T19:47:23.136+0000] {logging_mixin.py:120} INFO - [2024-03-27T19:47:23.136+0000] {dag.py:2585} INFO - Sync 1 DAGs
[2024-03-27T19:47:23.155+0000] {logging_mixin.py:120} INFO - [2024-03-27T19:47:23.155+0000] {dag.py:3340} INFO - Setting next_dagrun for consumer_test to None, run_after=None
[2024-03-27T19:47:23.171+0000] {processor.py:176} INFO - Processing /opt/airflow/dags/consumer.py took 0.081 seconds
[2024-03-27T19:47:45.881+0000] {processor.py:154} INFO - Started process (PID=42) to work on /opt/airflow/dags/consumer.py
[2024-03-27T19:47:45.882+0000] {processor.py:756} INFO - Processing file /opt/airflow/dags/consumer.py for tasks to queue
[2024-03-27T19:47:45.883+0000] {logging_mixin.py:120} INFO - [2024-03-27T19:47:45.883+0000] {dagbag.py:537} INFO - Filling up the DagBag from /opt/airflow/dags/consumer.py
[2024-03-27T19:47:45.900+0000] {processor.py:766} INFO - DAG(s) dict_keys(['consumer_test']) retrieved from /opt/airflow/dags/consumer.py
[2024-03-27T19:47:45.937+0000] {logging_mixin.py:120} INFO - [2024-03-27T19:47:45.937+0000] {dag.py:2585} INFO - Sync 1 DAGs
[2024-03-27T19:47:45.960+0000] {logging_mixin.py:120} INFO - [2024-03-27T19:47:45.960+0000] {dag.py:3340} INFO - Setting next_dagrun for consumer_test to None, run_after=None
[2024-03-27T19:47:45.980+0000] {processor.py:176} INFO - Processing /opt/airflow/dags/consumer.py took 0.101 seconds
[2024-03-27T19:48:19.412+0000] {processor.py:154} INFO - Started process (PID=91) to work on /opt/airflow/dags/consumer.py
[2024-03-27T19:48:19.414+0000] {processor.py:756} INFO - Processing file /opt/airflow/dags/consumer.py for tasks to queue
[2024-03-27T19:48:19.416+0000] {logging_mixin.py:120} INFO - [2024-03-27T19:48:19.416+0000] {dagbag.py:537} INFO - Filling up the DagBag from /opt/airflow/dags/consumer.py
[2024-03-27T19:48:19.545+0000] {processor.py:766} INFO - DAG(s) dict_keys(['consumer_test']) retrieved from /opt/airflow/dags/consumer.py
[2024-03-27T19:48:19.725+0000] {logging_mixin.py:120} INFO - [2024-03-27T19:48:19.725+0000] {dag.py:2585} INFO - Sync 1 DAGs
[2024-03-27T19:48:19.781+0000] {logging_mixin.py:120} INFO - [2024-03-27T19:48:19.781+0000] {dag.py:3340} INFO - Setting next_dagrun for consumer_test to None, run_after=None
[2024-03-27T19:48:19.815+0000] {processor.py:176} INFO - Processing /opt/airflow/dags/consumer.py took 0.429 seconds
[2024-03-27T19:48:49.981+0000] {processor.py:154} INFO - Started process (PID=150) to work on /opt/airflow/dags/consumer.py
[2024-03-27T19:48:49.990+0000] {processor.py:756} INFO - Processing file /opt/airflow/dags/consumer.py for tasks to queue
[2024-03-27T19:48:49.991+0000] {logging_mixin.py:120} INFO - [2024-03-27T19:48:49.991+0000] {dagbag.py:537} INFO - Filling up the DagBag from /opt/airflow/dags/consumer.py
[2024-03-27T19:48:50.051+0000] {processor.py:766} INFO - DAG(s) dict_keys(['consumer_test']) retrieved from /opt/airflow/dags/consumer.py
[2024-03-27T19:48:50.119+0000] {logging_mixin.py:120} INFO - [2024-03-27T19:48:50.119+0000] {dag.py:2585} INFO - Sync 1 DAGs
[2024-03-27T19:48:50.169+0000] {logging_mixin.py:120} INFO - [2024-03-27T19:48:50.169+0000] {dag.py:3340} INFO - Setting next_dagrun for consumer_test to None, run_after=None
[2024-03-27T19:48:50.207+0000] {processor.py:176} INFO - Processing /opt/airflow/dags/consumer.py took 0.235 seconds
[2024-03-27T19:49:25.422+0000] {processor.py:154} INFO - Started process (PID=43) to work on /opt/airflow/dags/consumer.py
[2024-03-27T19:49:25.423+0000] {processor.py:756} INFO - Processing file /opt/airflow/dags/consumer.py for tasks to queue
[2024-03-27T19:49:25.423+0000] {logging_mixin.py:120} INFO - [2024-03-27T19:49:25.423+0000] {dagbag.py:537} INFO - Filling up the DagBag from /opt/airflow/dags/consumer.py
[2024-03-27T19:49:25.445+0000] {processor.py:766} INFO - DAG(s) dict_keys(['consumer_test']) retrieved from /opt/airflow/dags/consumer.py
[2024-03-27T19:49:25.479+0000] {logging_mixin.py:120} INFO - [2024-03-27T19:49:25.479+0000] {dag.py:2585} INFO - Sync 1 DAGs
[2024-03-27T19:49:25.495+0000] {logging_mixin.py:120} INFO - [2024-03-27T19:49:25.494+0000] {dag.py:3340} INFO - Setting next_dagrun for consumer_test to None, run_after=None
[2024-03-27T19:49:25.514+0000] {processor.py:176} INFO - Processing /opt/airflow/dags/consumer.py took 0.094 seconds
[2024-03-27T19:49:58.041+0000] {processor.py:154} INFO - Started process (PID=93) to work on /opt/airflow/dags/consumer.py
[2024-03-27T19:49:58.044+0000] {processor.py:756} INFO - Processing file /opt/airflow/dags/consumer.py for tasks to queue
[2024-03-27T19:49:58.048+0000] {logging_mixin.py:120} INFO - [2024-03-27T19:49:58.048+0000] {dagbag.py:537} INFO - Filling up the DagBag from /opt/airflow/dags/consumer.py
[2024-03-27T19:49:58.224+0000] {processor.py:766} INFO - DAG(s) dict_keys(['consumer_test']) retrieved from /opt/airflow/dags/consumer.py
[2024-03-27T19:49:58.392+0000] {logging_mixin.py:120} INFO - [2024-03-27T19:49:58.390+0000] {dag.py:2585} INFO - Sync 1 DAGs
[2024-03-27T19:49:58.617+0000] {logging_mixin.py:120} INFO - [2024-03-27T19:49:58.615+0000] {dag.py:3340} INFO - Setting next_dagrun for consumer_test to None, run_after=None
[2024-03-27T19:49:58.995+0000] {processor.py:176} INFO - Processing /opt/airflow/dags/consumer.py took 0.965 seconds
[2024-03-27T19:54:17.721+0000] {processor.py:154} INFO - Started process (PID=35) to work on /opt/airflow/dags/consumer.py
[2024-03-27T19:54:17.723+0000] {processor.py:756} INFO - Processing file /opt/airflow/dags/consumer.py for tasks to queue
[2024-03-27T19:54:17.724+0000] {logging_mixin.py:120} INFO - [2024-03-27T19:54:17.724+0000] {dagbag.py:537} INFO - Filling up the DagBag from /opt/airflow/dags/consumer.py
[2024-03-27T19:54:17.763+0000] {processor.py:766} INFO - DAG(s) dict_keys(['consumer_test']) retrieved from /opt/airflow/dags/consumer.py
[2024-03-27T19:54:17.820+0000] {logging_mixin.py:120} INFO - [2024-03-27T19:54:17.820+0000] {dag.py:2585} INFO - Sync 1 DAGs
[2024-03-27T19:54:17.857+0000] {logging_mixin.py:120} INFO - [2024-03-27T19:54:17.856+0000] {dag.py:3340} INFO - Setting next_dagrun for consumer_test to None, run_after=None
[2024-03-27T19:54:17.883+0000] {processor.py:176} INFO - Processing /opt/airflow/dags/consumer.py took 0.163 seconds
